Workbook

Sheet Trang bìa
C2: Công ty Cổ phần AgriPack
B6: Mô tả | E6: Mã màu
B7: Mã cổ phiếu | C7: Công ty Cổ phần AgriPack (chưa niêm yết, chưa có mã cổ phiếu) | E7: Aaa | F7: Giả định (ô nhập liệu)
B8: Sàn niêm yết | C8: Chưa niêm yết – định giá cổ phần cho vòng gọi vốn Series A | E8: Aaa | F8: Dữ liệu lịch sử
B9: Ngày update | C9: 46302 | E9: Aaa | F9: Công thức
B10: Miêu tả ngắn gọn | C10: Mô hình định giá cổ phần trước vòng gọi vốn bằng DCF, VC Method và Multiples. | E10: Aaa | F10: Link đến các trang khác
B11: Thông tin doanh nghiệp | F11: Note (ghi chú, nguồn, lý do)
E13: Thông tin về mô hình
B14: Cấu trúc các Tab | E14: Tiền tệ | F14: VND
B15: Trang bìa | C15: Thông tin chung, mã màu, cấu trúc file và thông tin mô hình | E15: Đơn vị | F15: Nghìn đồng; tỷ đồng ở Multiples, Summary, Sensitivity, Chart_Data
B16: Hướng dẫn | C16: Hướng dẫn của file mẫu (giảng viên) | E16: Thời điểm định giá | F16: 01/10/2026 (BCTC đến 31/12/2025)
B17: Investment | C17: Kế hoạch đầu tư tài sản của file mẫu | E17: Rf (TPCP 10 năm, 01/10/2026) | F17: ='Discount rate'!B12 -> 0.04588
B18: Income Statement | C18: Báo cáo kết quả kinh doanh 2023A–2030E (theo chức năng, VAS) | E18: WACC | F18: ='Discount rate'!E4 -> 0.14130984
B19: Balance Sheet | C19: Bảng cân đối kế toán 2023A–2030E | E19: Pre-money khuyến nghị (tỷ đồng) | F19: =Summary!B8 -> 26.007498
B20: Cash Flow Statement | C20: Báo cáo lưu chuyển tiền tệ 2023A–2030E
B21: Discount rate | C21: Chi phí vốn: Rf, ERP, CRP, beta, Ke, Kd và WACC
B22: Assumption | C22: Tỷ lệ giả định tổng hợp 2026E–2030E, g và RONIC
B23: Drivers | C23: Động lực dự phóng: sản lượng × giá, chi phí, CAPEX, VLĐ, vay, thuế, kịch bản
B24: Pro Forma | C24: KQKD dự phóng, CAPEX, vốn lưu động và nhu cầu vốn
B25: DCF | C25: Định giá chiết khấu dòng tiền tự do (FCFF)
B26: VCM | C26: Định giá theo VC Method (thoái vốn 2030, tỷ lệ thất bại 40%)
B27: Multiples | C27: Định giá theo bội số so sánh EV/EBITDA và P/E
B28: Summary | C28: Tổng hợp định giá, khoảng giá trị, kịch bản và độ nhạy theo nhân tố
B29: Sensitivity | C29: Bảng độ nhạy DCF và VC Method
B30: Checks | C30: Kiểm tra cân đối và liên kết giữa các sheet

Sheet Hướng dẫn
B4: Three Statement Model
I6: Năm hiện tại | J6: 2026
C8: LƯU Ý
B9: Model Legend
C11: Ô nhập liệu | D11: ABC | E11: Chỉ nhập dữ liệu vào những ô màu vàng này
C13: Tất cả các ô khác đã được nhập sẵn hàm hoặc là ô chứa dữ liệu cho trước. KHÔNG thay đổi những ô này!

Sheet Investment
A1: Các khoản đầu tư dự kiến 5 năm
B3: Đơn giá (nghìn đồng) | C3: Số lượng | D3: Thành tiền | E3: Tháng | F3: Năm | G3: Thời gian sử dụng | H3: Giá trị còn lại
D4: =SUM(D5:D7) -> 24090000 | F4: ='Cash Flow Statement'!E2+1 -> 2026
A5: Nhà máy sản xuất | B5: 30550000 | C5: 0 | D5: =B5*C5 -> 0 | E5: 10 | G5: 8
A6: Thiết bị sản xuất | B6: 3600000 | C6: 5 | D6: =B6*C6 -> 18000000 | E6: 11 | G6: 5
A7: Xe tải chở hàng | B7: 1218000 | C7: 5 | D7: =B7*C7 -> 6090000 | E7: 11 | G7: 5
D8: =SUM(D9:D10) -> 77100000 | F8: =F4+1 -> 2027
A9: Nhà máy sản xuất | B9: 30550000 | C9: 2 | D9: =B9*C9 -> 61100000 | E9: 10 | G9: 7
A10: Kho hàng | B10: 4000000 | C10: 4 | D10: =B10*C10 -> 16000000 | E10: 5 | G10: 7
D11: =SUM(D12) -> 22640000 | F11: =F8+1 -> 2028 | I11: Đầu tư mạnh tăng trưởng mở rộng KD
A12: Thiết bị sản xuất | B12: 5660000 | C12: 4 | D12: =B12*C12 -> 22640000 | E12: 9 | G12: 5 | I12: CAPEX/Revenue = 60%
D13: =SUM(D14) -> 35220000 | F13: =F11+1 -> 2029
A14: Thiết bị sản xuất | B14: 5870000 | C14: 6 | D14: =B14*C14 -> 35220000 | E14: 4 | G14: 8
D15: =SUM(D16:D17) -> 32460000 | F15: =F13+1 -> 2030
A16: Nâng cấp văn phòng | B16: 8115000 | C16: 4 | D16: =B16*C16 -> 32460000 | E16: 1 | G16: 6

Sheet Income Statement
A1: Income Statement | D1: Đơn vị: Nghìn đồng
B2: ='Hướng dẫn'!J6-3 -> 2023 | C2: =B2+1 -> 2024 | D2: =C2+1 -> 2025 | E2: =D2+1 -> 2026 | F2: =E2+1 -> 2027 | G2: =F2+1 -> 2028 | H2: =G2+1 -> 2029 | I2: =H2+1 -> 2030 | J2: Ngoài kỳ dự phóng 5 năm – không sử dụng
A3: Doanh thu bán hàng
A4: Doanh thu 1 | B4: 15055000 | C4: 24088000 | D4: 38059040 | E4: =Drivers!F14 -> 51242691 | F4: =Drivers!G14 -> 65334432 | G4: =Drivers!H14 -> 79969344 | H4: =Drivers!I14 -> 1.1011779e+08 | I4: =Drivers!J14 -> 1.4040018e+08
A5: Doanh thu 2 | B5: 3020000 | C5: 4228000 | D5: 5898060 | E5: =Drivers!F21 -> 7339545.9 | F5: =Drivers!G21 -> 8983604.1 | G5: =Drivers!H21 -> 10629400 | H5: =Drivers!I21 -> 13877745 | I5: =Drivers!J21 -> 16986360
A6: Doanh thu 3 | B6: 1520000 | C6: 2280000 | D6: 2736000 | E6: =Drivers!F28 -> 3610152 | F6: =Drivers!G28 -> 4763595.6 | G6: =Drivers!H28 -> 6188863.4 | H6: =Drivers!I28 -> 8794374.8 | I6: =Drivers!J28 -> 11782703
A7: Doanh thu 4 | B7: 0 | C7: 566000 | D7: 1188600 | E7: =Drivers!F35 -> 1930286.4 | F7: =Drivers!G35 -> 2938861 | G7: =Drivers!H35 -> 4325268.7 | H7: =Drivers!I35 -> 7463251.2 | I7: =Drivers!J35 -> 10984040
A9: (-) Khoản giảm trừ | B9: -156760 | C9: -233715 | D9: -335171.9 | E9: =-SUM(E4:E7)*Drivers!F38 -> -448858.73 | F9: =-SUM(F4:F7)*Drivers!G38 -> -574143.45 | G9: =-SUM(G4:G7)*Drivers!H38 -> -707790.14 | H9: =-SUM(H4:H7)*Drivers!I38 -> -981772.11 | I9: =-SUM(I4:I7)*Drivers!J38 -> -1261073
A11: Doanh thu thuần | B11: 19438240 | C11: 30928285 | D11: 47546528 | E11: =SUM(E4:E10) -> 63673817 | F11: =SUM(F4:F10) -> 81446349 | G11: =SUM(G4:G10) -> 1.0040509e+08 | H11: =SUM(H4:H10) -> 1.3927139e+08 | I11: =SUM(I4:I10) -> 1.7889221e+08
A13: Giá vốn hàng bán
A14: Chi phí biến đổi | B14: 4956751.2 | C14: 7732071.2 | D14: 11648899 | E14: =Drivers!F56 -> 15918454 | F14: =Drivers!G56 -> 20361587 | G14: =Drivers!H56 -> 25603297 | H14: =Drivers!I56 -> 37603274 | I14: =Drivers!J56 -> 47406435
A15: Chi phí cố định | B15: 1055000 | C15: 1160500 | D15: 1276550 | E15: =Drivers!F57 -> 1404205 | F15: =Drivers!G57 -> 1544625.5 | G15: =Drivers!H57 -> 1699088.1 | H15: =Drivers!I57 -> 2768996.9 | I15: =Drivers!J57 -> 3045896.5
A16: Tiền lương bộ phận sản xuất (70% quỹ lương) | B16: =Drivers!$C$167*B53 -> 4894400 | C16: =Drivers!$C$167*C53 -> 5383840 | D16: =Drivers!$C$167*D53 -> 7537376 | E16: =Drivers!$C$167*E53 -> 10028626 | F16: =Drivers!$C$167*F53 -> 12827800 | G16: =Drivers!$C$167*G53 -> 16165219 | H16: =Drivers!$C$167*H53 -> 22910143 | I16: =Drivers!$C$167*I53 -> 28801646
A17: Khấu hao TSCĐ sản xuất (90% khấu hao) | B17: =Drivers!$C$168*B69 -> 1288980 | C17: =Drivers!$C$168*C69 -> 2137752 | D17: =Drivers!$C$168*D69 -> 2818756.8 | E17: =Drivers!$C$168*E69 -> 3367885 | F17: =Drivers!$C$168*F69 -> 4743239.4 | G17: =Drivers!$C$168*G69 -> 6062670.3 | H17: =Drivers!$C$168*H69 -> 13111107 | I17: =Drivers!$C$168*I69 -> 14916065
A18: Tổng Giá vốn hàng bán | B18: =SUM(B14:B17) -> 12195131 | C18: =SUM(C14:C17) -> 16414163 | D18: =SUM(D14:D17) -> 23281582 | E18: =SUM(E14:E17) -> 30719170 | F18: =SUM(F14:F17) -> 39477252 | G18: =SUM(G14:G17) -> 49530274 | H18: =SUM(H14:H17) -> 76393522 | I18: =SUM(I14:I17) -> 94170042
A19: Lợi nhuận gộp | B19: =B11-B18 -> 7243108.8 | C19: =C11-C18 -> 14514122 | D19: =D11-D18 -> 24264946 | E19: =E11-E18 -> 32954647 | F19: =F11-F18 -> 41969097 | G19: =G11-G18 -> 50874812 | H19: =H11-H18 -> 62877865 | I19: =I11-I18 -> 84722167
A20: Biên lợi nhuận gộp | B20: =B19/B11 -> 0.37262164 | C20: =C19/C11 -> 0.46928311 | D20: =D19/D11 -> 0.51034107 | E20: =E19/E11 -> 0.51755412 | F20: =F19/F11 -> 0.51529746 | G20: =G19/G11 -> 0.50669557 | H20: =H19/H11 -> 0.45147727 | I20: =I19/I11 -> 0.47359339
A21: Chi phí
A22: Chi phí Bán hàng và quản lý doanh nghiệp
A23: Tiền lương bộ phận bán hàng & quản lý (30% quỹ lương) | B23: =(1-Drivers!$C$167)*B53 -> 2097600 | C23: =(1-Drivers!$C$167)*C53 -> 2307360 | D23: =(1-Drivers!$C$167)*D53 -> 3230304 | E23: =(1-Drivers!$C$167)*E53 -> 4297982.6 | F23: =(1-Drivers!$C$167)*F53 -> 5497628.6 | G23: =(1-Drivers!$C$167)*G53 -> 6927951 | H23: =(1-Drivers!$C$167)*H53 -> 9818632.7 | I23: =(1-Drivers!$C$167)*I53 -> 12343562
A24: Thuê mặt bằng | B24: 3977000 | C24: 5368950 | D24: 7570219.5 | E24: =Drivers!F67 -> 8478645.8 | F24: =Drivers!G67 -> 9496083.3 | G24: =Drivers!H67 -> 10920496 | H24: =Drivers!I67 -> 14196645 | I24: =Drivers!J67 -> 15900242
A25: Khấu hao TSCĐ bộ phận bán hàng & quản lý (10% khấu hao) | B25: =(1-Drivers!$C$168)*B69 -> 143220 | C25: =(1-Drivers!$C$168)*C69 -> 237528 | D25: =(1-Drivers!$C$168)*D69 -> 313195.2 | E25: =(1-Drivers!$C$168)*E69 -> 374209.44 | F25: =(1-Drivers!$C$168)*F69 -> 527026.6 | G25: =(1-Drivers!$C$168)*G69 -> 673630.03 | H25: =(1-Drivers!$C$168)*H69 -> 1456789.7 | I25: =(1-Drivers!$C$168)*I69 -> 1657340.5
A26: Sửa chữa, bảo dưỡng | B26: 950000 | C26: 1615000 | D26: 2083350 | E26: =Drivers!F69 -> 2801647.9 | F26: =Drivers!G69 -> 3583639.4 | G26: =Drivers!H69 -> 4417823.8 | H26: =Drivers!I69 -> 6127941 | I26: =Drivers!J69 -> 7871257.2
A27: Furniture & Fixtures | B27: 0 | C27: 0 | D27: 0 | E27: 0 | F27: 0 | G27: 0 | H27: 0 | I27: 0
A28: Chi phí dịch vụ chung (điện, nước...) | B28: 1200000 | C28: 1800000 | D28: 2250000 | E28: =Drivers!F71 -> 3183690.8 | F28: =Drivers!G71 -> 4072317.4 | G28: =Drivers!H71 -> 5020254.3 | H28: =Drivers!I71 -> 6963569.3 | I28: =Drivers!J71 -> 8944610.5
A29: Internet & Communications | B29: 0 | C29: 0 | D29: 0 | E29: 0 | F29: 0 | G29: 0 | H29: 0 | I29: 0
A30: Infrastructure Services | B30: 0 | C30: 0 | D30: 0 | E30: 0 | F30: 0 | G30: 0 | H30: 0 | I30: 0
A31: Software | B31: 0 | C31: 0 | D31: 0 | E31: 0 | F31: 0 | G31: 0 | H31: 0 | I31: 0
A32: Bank Service Charges | B32: 0 | C32: 0 | D32: 0 | E32: 0 | F32: 0 | G32: 0 | H32: 0 | I32: 0
A33: Business Licenses and Permits | B33: 0 | C33: 0 | D33: 0 | E33: 0 | F33: 0 | G33: 0 | H33: 0 | I33: 0
A34: Conferences, Dues, and Subscriptions | B34: 0 | C34: 0 | D34: 0 | E34: 0 | F34: 0 | G34: 0 | H34: 0 | I34: 0
A35: Văn phòng phẩm | B35: 0 | C35: 0 | D35: 0 | E35: 0 | F35: 0 | G35: 0 | H35: 0 | I35: 0
A36: Gifts | B36: 0 | C36: 0 | D36: 0 | E36: 0 | F36: 0 | G36: 0 | H36: 0 | I36: 0
A37: Printing , Postage and Delivery | B37: 0 | C37: 0 | D37: 0 | E37: 0 | F37: 0 | G37: 0 | H37: 0 | I37: 0
A38: Miscellaneous | B38: 0 | C38: 0 | D38: 0 | E38: 0 | F38: 0 | G38: 0 | H38: 0 | I38: 0
A39: Recruiting Expense | B39: 0 | C39: 0 | D39: 0 | E39: 0 | F39: 0 | G39: 0 | H39: 0 | I39: 0
A40: Hỗ trợ tiền ăn cho CNV | B40: 2150000 | C40: 2580000 | D40: 3096000 | E40: =Drivers!F65 -> 4011450.5 | F40: =Drivers!G65 -> 5131120 | G40: =Drivers!H65 -> 6466087.6 | H40: =Drivers!I65 -> 9164057.2 | I40: =Drivers!J65 -> 11520658
A41: Equipment Rental | B41: 0 | C41: 0 | D41: 0 | E41: 0 | F41: 0 | G41: 0 | H41: 0 | I41: 0
A42: Other Tech Expense | B42: 0 | C42: 0 | D42: 0 | E42: 0 | F42: 0 | G42: 0 | H42: 0 | I42: 0
A43: Professional Services (dùng cho: Kiểm nghiệm, chứng nhận & R&D vật liệu) | B43: 0 | C43: 0 | D43: 0 | E43: =Drivers!F75 -> 382042.9 | F43: =Drivers!G75 -> 488678.09 | G43: =Drivers!H75 -> 602430.52 | H43: =Drivers!I75 -> 835628.32 | I43: =Drivers!J75 -> 1073353.3
...

Sheet Balance Sheet
A1: Balance Sheet | F1: Đơn vị: Nghìn đồng
C2: ='Hướng dẫn'!J6-3 -> 2023 | E2: =C2+1 -> 2024 | F2: =E2+1 -> 2025 | G2: =F2+1 -> 2026 | H2: =G2+1 -> 2027 | I2: =H2+1 -> 2028 | J2: =I2+1 -> 2029 | K2: =J2+1 -> 2030 | L2: Ngoài kỳ dự phóng – không sử dụng
A3: Tài sản ngắn hạn | C3: 01/01/2023 (đầu kỳ) | D3: 31/12/2023
A4: Tiền và các khoản tương đương tiền
B5: Tiền mặt | C5: 910000 | D5: 43988.8 | E5: 1735532.6 | F5: 2933481.8 | G5: ='Cash Flow Statement'!F34 -> 38400238 | H5: ='Cash Flow Statement'!G34 -> 36454184 | I5: ='Cash Flow Statement'!H34 -> 21617752 | J5: ='Cash Flow Statement'!I34 -> 14952947 | K5: ='Cash Flow Statement'!J34 -> 12623217
B6: Tổng tiền mặt | C6: 910000 | D6: 43988.8 | E6: 1735532.6 | F6: 2933481.8 | G6: =SUM(G5) -> 38400238 | H6: =SUM(H5) -> 36454184 | I6: =SUM(I5) -> 21617752 | J6: =SUM(J5) -> 14952947 | K6: =SUM(K5) -> 12623217
A7: Hàng tồn kho
B8: Hàng tồn kho | C8: 1785000 | D8: 2499000 | E8: 2998800 | F8: 3748500 | G8: =Drivers!F106 -> 4745934 | H8: =Drivers!G106 -> 6001702.1 | I8: =Drivers!H106 -> 7480105.5 | J8: =Drivers!I106 -> 11613941 | K8: =Drivers!J106 -> 13822557
B9: Tổng hàng tồn kho | C9: 1785000 | D9: 2499000 | E9: 2998800 | F9: 3748500 | G9: =SUM(G8) -> 4745934 | H9: =SUM(H8) -> 6001702.1 | I9: =SUM(I8) -> 7480105.5 | J9: =SUM(J8) -> 11613941 | K9: =SUM(K8) -> 13822557
A10: Khoản phải thu
B11: Phải thu khách hàng | C11: 1050000 | D11: 1260000 | E11: 1537200 | F11: 1767780 | G11: =Drivers!F108 -> 3140078.6 | H11: =Drivers!G108 -> 4909095 | I11: =Drivers!H108 -> 7152143.2 | J11: =Drivers!I108 -> 11446963 | K11: =Drivers!J108 -> 14703469
B12: Tổng khoản phải thu | C12: 1050000 | D12: 1260000 | E12: 1537200 | F12: 1767780 | G12: =SUM(G11) -> 3140078.6 | H12: =SUM(H11) -> 4909095 | I12: =SUM(I11) -> 7152143.2 | J12: =SUM(J11) -> 11446963 | K12: =SUM(K11) -> 14703469
A13: Tài sản ngắn hạn khác
B14: Other Receivable | C14: 0 | D14: 0 | E14: 0 | F14: 0 | G14: 0 | H14: 0 | I14: 0 | J14: 0 | K14: 0
B15: Chi phí trả trước | C15: 890000 | D15: 1068000 | E15: 1495200 | F15: 1794240 | G15: =Drivers!F110*$F$15/$F$19 -> 2204363.7 | H15: =Drivers!G110*$F$15/$F$19 -> 2819642.1 | I15: =Drivers!H110*$F$15/$F$19 -> 3475986.5 | J15: =Drivers!I110*$F$15/$F$19 -> 4821523.3 | K15: =Drivers!J110*$F$15/$F$19 -> 6193181.3
B16: Prepaid Insurance | C16: - | D16: - | E16: - | F16: - | G16: 0 | H16: 0 | I16: 0 | J16: 0 | K16: 0
B17: Unbilled Revenue | C17: - | D17: - | E17: - | F17: - | G17: 0 | H17: 0 | I17: 0 | J17: 0 | K17: 0
B18: Tài sản ngắn hạn khác | C18: 150000 | D18: 165000 | E18: 214500 | F18: 278850 | G18: =Drivers!F110*$F$18/$F$19 -> 342588.96 | H18: =Drivers!G110*$F$18/$F$19 -> 438211.84 | I18: =Drivers!H110*$F$18/$F$19 -> 540216.94 | J18: =Drivers!I110*$F$18/$F$19 -> 749332.18 | K18: =Drivers!J110*$F$18/$F$19 -> 962507.03
B19: Tổng tài sản ngắn hạn khác | C19: 1040000 | D19: 1233000 | E19: 1709700 | F19: 2073090 | G19: =SUM(G14:G18) -> 2546952.7 | H19: =SUM(H14:H18) -> 3257854 | I19: =SUM(I14:I18) -> 4016203.5 | J19: =SUM(J14:J18) -> 5570855.4 | K19: =SUM(K14:K18) -> 7155688.4
A21: Tổng tài sản ngắn hạn | C21: 4785000 | D21: 5035988.8 | E21: 7981232.5 | F21: 10522852 | G21: =SUM(G6,G9,G12,G19) -> 48833203 | H21: =SUM(H6,H9,H12,H19) -> 50622835 | I21: =SUM(I6,I9,I12,I19) -> 40266204 | J21: =SUM(J6,J9,J12,J19) -> 43584707 | K21: =SUM(K6,K9,K12,K19) -> 48304931
A22: Tài sản dài hạn
A23: Khấu khao
B24: Khấu hao lũy kế | C24: 2850000 | D24: 4282200 | E24: 6657480 | F24: 9789432 | G24: =SUM(F24,'Income Statement'!E69) -> 13531526 | H24: =SUM(G24,'Income Statement'!F69) -> 18801792 | I24: =SUM(H24,'Income Statement'!G69) -> 25538093 | J24: =SUM(I24,'Income Statement'!H69) -> 40105990 | K24: =SUM(J24,'Income Statement'!I69) -> 56679395
B25: Accumulated Amortization | C25: 0 | D25: 0 | E25: 0 | F25: 0 | G25: =SUM(F25,'Income Statement'!E70) -> 0 | H25: =SUM(G25,'Income Statement'!F70) -> 0 | I25: =SUM(H25,'Income Statement'!G70) -> 0 | J25: =SUM(I25,'Income Statement'!H70) -> 0 | K25: =SUM(J25,'Income Statement'!I70) -> 0
A26: Tài sản dài hạn
B27: Tài sản cố định vô hình | C27: 985000 | D27: 985000 | E27: 1020000 | F27: 1020000 | G27: =F27 -> 1020000 | H27: =G27 -> 1020000 | I27: =H27 -> 1020000 | J27: =I27 -> 1020000 | K27: =J27 -> 1020000
B28: Thiết bị, nhà xưởng | C28: 10220000 | D28: 13797000 | E28: 19315800 | F28: 21633696 | G28: =SUM(F28,Drivers!F96) -> 34368459 | H28: =SUM(G28,Drivers!G96) -> 46585412 | I28: =SUM(H28,Drivers!H96) -> 1.1184872e+08 | J28: =SUM(I28,Drivers!I96) -> 1.2856128e+08 | K28: =SUM(J28,Drivers!J96) -> 1.4645051e+08
B29: Văn phòng | C29: 3580000 | D29: 5012000 | E29: 5763800 | F29: 8530424 | G29: =F29 -> 8530424 | H29: =G29 -> 8530424 | I29: =H29 -> 8530424 | J29: =I29 -> 8530424 | K29: =J29 -> 8530424
A30: Tổng tài sản dài hạn | C30: 11935000 | D30: 15511800 | E30: 19442120 | F30: 21394688 | G30: =SUM(G27:G29)-G24-G25 -> 30387357 | H30: =SUM(H27:H29)-H24-H25 -> 37334043 | I30: =SUM(I27:I29)-I24-I25 -> 95861049 | J30: =SUM(J27:J29)-J24-J25 -> 98005719 | K30: =SUM(K27:K29)-K24-K25 -> 99321535
A32: Tổng tài sản | C32: 16720000 | D32: 20547789 | E32: 27423353 | F32: 31917540 | G32: =SUM(G21,G30) -> 79220560 | H32: =SUM(H21,H30) -> 87956878 | I32: =SUM(I21,I30) -> 1.3612725e+08 | J32: =SUM(J21,J30) -> 1.4159043e+08 | K32: =SUM(K21,K30) -> 1.4762647e+08
C33: 0 | D33: 0 | E33: 0 | F33: 0
A34: Nợ phải trả và Vốn chủ sở hữu
A35: Nợ ngắn hạn
A36: Khoản phải trả
B37: Phải trả người bán | C37: 120000 | D37: 156000 | E37: 202800 | F37: 263640 | G37: =Drivers!F112 -> 474593.4 | H37: =Drivers!G112 -> 720204.25 | I37: =Drivers!H112 -> 1122015.8 | J37: =Drivers!I112 -> 1659134.4 | K37: =Drivers!J112 -> 2073383.5
B38: Tổng khoản khải trả | C38: 120000 | D38: 156000 | E38: 202800 | F38: 263640 | G38: =SUM(G37) -> 474593.4 | H38: =SUM(H37) -> 720204.25 | I38: =SUM(I37) -> 1122015.8 | J38: =SUM(J37) -> 1659134.4 | K38: =SUM(K37) -> 2073383.5
A39: Credit Cards
B40: Credit Card 1 | C40: 0 | D40: 0 | E40: 0 | F40: 0 | G40: 0 | H40: 0 | I40: 0 | J40: 0 | K40: 0
B41: Credit Card 2 | C41: 0 | D41: 0 | E41: 0 | F41: 0 | G41: 0 | H41: 0 | I41: 0 | J41: 0 | K41: 0
B42: Total Credit Cards Payable | C42: 0 | D42: 0 | E42: 0 | F42: 0 | G42: =SUM(G40:G41) -> 0 | H42: =SUM(H40:H41) -> 0 | I42: =SUM(I40:I41) -> 0 | J42: =SUM(J40:J41) -> 0 | K42: =SUM(K40:K41) -> 0
...

Sheet Cash Flow Statement
A1: Statement of Cash Flows | E1: Đơn vị: Nghìn đồng
C2: ='Income Statement'!B2 -> 2023 | D2: =C2+1 -> 2024 | E2: =D2+1 -> 2025 | F2: =E2+1 -> 2026 | G2: =F2+1 -> 2027 | H2: =G2+1 -> 2028 | I2: =H2+1 -> 2029 | J2: =I2+1 -> 2030 | K2: Ngoài kỳ dự phóng – không sử dụng
A3: Hoạt động kinh doanh
B4: Lợi nhuận sau thuế | C4: -4309011.2 | D4: -503276.25 | E4: 4420495.2 | F4: ='Income Statement'!E78 -> 6579139.9 | G4: ='Income Statement'!F78 -> 8455162.4 | H4: ='Income Statement'!G78 -> 8572661.9 | I4: ='Income Statement'!H78 -> 4848321.5 | J4: ='Income Statement'!I78 -> 13374146
B6: Khấu hao | C6: 1432200 | D6: 2375280 | E6: 3131952 | F6: ='Income Statement'!E69 -> 3742094.4 | G6: ='Income Statement'!F69 -> 5270266 | H6: ='Income Statement'!G69 -> 6736300.3 | I6: ='Income Statement'!H69 -> 14567897 | J6: ='Income Statement'!I69 -> 16573405
A8: Biến động Tài sản ngắn hạn
B9: Khoản phải thu | C9: -210000 | D9: -277200 | E9: -230580 | F9: ='Balance Sheet'!F11-'Balance Sheet'!G11 -> -1372298.6 | G9: ='Balance Sheet'!G11-'Balance Sheet'!H11 -> -1769016.4 | H9: ='Balance Sheet'!H11-'Balance Sheet'!I11 -> -2243048.2 | I9: ='Balance Sheet'!I11-'Balance Sheet'!J11 -> -4294820.1 | J9: ='Balance Sheet'!J11-'Balance Sheet'!K11 -> -3256506
B10: Hàng tồn kho | C10: -714000 | D10: -499800 | E10: -749700 | F10: ='Balance Sheet'!F9-'Balance Sheet'!G9 -> -997434.04 | G10: ='Balance Sheet'!G9-'Balance Sheet'!H9 -> -1255768.1 | H10: ='Balance Sheet'!H9-'Balance Sheet'!I9 -> -1478403.4 | I10: ='Balance Sheet'!I9-'Balance Sheet'!J9 -> -4133835.5 | J10: ='Balance Sheet'!J9-'Balance Sheet'!K9 -> -2208615.7
B11: Tài sản ngắn hạn khác | C11: -193000 | D11: -476700 | E11: -363390 | F11: ='Balance Sheet'!F19-'Balance Sheet'!G19 -> -473862.68 | G11: ='Balance Sheet'!G19-'Balance Sheet'!H19 -> -710901.28 | H11: ='Balance Sheet'!H19-'Balance Sheet'!I19 -> -758349.51 | I11: ='Balance Sheet'!I19-'Balance Sheet'!J19 -> -1554652 | J11: ='Balance Sheet'!J19-'Balance Sheet'!K19 -> -1584832.9
A12: Biến động Nợ ngắn hạn
B13: Khoản phải trả | C13: 36000 | D13: 46800 | E13: 60840 | F13: ='Balance Sheet'!G38-'Balance Sheet'!F38 -> 210953.4 | G13: ='Balance Sheet'!H38-'Balance Sheet'!G38 -> 245610.85 | H13: ='Balance Sheet'!I38-'Balance Sheet'!H38 -> 401811.57 | I13: ='Balance Sheet'!J38-'Balance Sheet'!I38 -> 537118.6 | J13: ='Balance Sheet'!K38-'Balance Sheet'!J38 -> 414249.07
B14: ='Balance Sheet'!A43 -> Nợ vay ngắn hạn | C14: -10000 | D14: 18000 | E14: -5400 | F14: ='Balance Sheet'!G45-'Balance Sheet'!F45 -> 0 | G14: ='Balance Sheet'!H45-'Balance Sheet'!G45 -> 0 | H14: ='Balance Sheet'!I45-'Balance Sheet'!H45 -> 0 | I14: ='Balance Sheet'!J45-'Balance Sheet'!I45 -> 0 | J14: ='Balance Sheet'!K45-'Balance Sheet'!J45 -> 0
B15: Nợ ngắn hạn khác | C15: 10800 | D15: 14040 | E15: 18252 | F15: =('Balance Sheet'!G53-'Balance Sheet'!F53)+('Balance Sheet'!G48-'Balance Sheet'!F48) -> 48255.634 | G15: =('Balance Sheet'!H53-'Balance Sheet'!G53)+('Balance Sheet'!H48-'Balance Sheet'!G48) -> 35545.064 | H15: =('Balance Sheet'!I53-'Balance Sheet'!H53)+('Balance Sheet'!I48-'Balance Sheet'!H48) -> 37917.476 | I15: =('Balance Sheet'!J53-'Balance Sheet'!I53)+('Balance Sheet'!J48-'Balance Sheet'!I48) -> 77732.599 | J15: =('Balance Sheet'!K53-'Balance Sheet'!J53)+('Balance Sheet'!K48-'Balance Sheet'!J48) -> 79241.646
A17: Lưu chuyển tiền thuần từ hoạt động kinh doanh | C17: -3957011.2 | D17: 697143.75 | E17: 6282469.2 | F17: =SUM(F4:F16) -> 7736847.9 | G17: =SUM(G4:G16) -> 10270899 | H17: =SUM(H4:H16) -> 11268890 | I17: =SUM(I4:I16) -> 10047762 | J17: =SUM(J4:J16) -> 23391087
A19: Đầu tư
B20: Biến động Tài sản cố định | C20: -5009000 | D20: -6305600 | E20: -5084520 | F20: =SUM('Balance Sheet'!F27:F29)-SUM('Balance Sheet'!G27:G29) -> -12734763 | G20: =SUM('Balance Sheet'!G27:G29)-SUM('Balance Sheet'!H27:H29) -> -12216952 | H20: =SUM('Balance Sheet'!H27:H29)-SUM('Balance Sheet'!I27:I29) -> -65263306 | I20: =SUM('Balance Sheet'!I27:I29)-SUM('Balance Sheet'!J27:J29) -> -16712566 | J20: =SUM('Balance Sheet'!J27:J29)-SUM('Balance Sheet'!K27:K29) -> -17889221
A22: Lưu chuyển tiền thuần từ hoạt động đầu tư | C22: -5009000 | D22: -6305600 | E22: -5084520 | F22: =SUM(F20:F21) -> -12734763 | G22: =SUM(G20:G21) -> -12216952 | H22: =SUM(H20:H21) -> -65263306 | I22: =SUM(I20:I21) -> -16712566 | J22: =SUM(J20:J21) -> -17889221
A24: Tài chính
B25: Nhận vốn góp cổ phần | C25: 8100000 | D25: 7000000 | E25: 0 | F25: ='Balance Sheet'!G69 -> 40464671 | G25: ='Balance Sheet'!H69 -> 0 | H25: ='Balance Sheet'!I69 -> 0 | I25: ='Balance Sheet'!J69 -> 0 | J25: ='Balance Sheet'!K69 -> 0
B26: Vay (trả) nợ dài hạn | C26: 0 | D26: 300000 | E26: 0 | F26: =('Balance Sheet'!G58-'Balance Sheet'!F58) -> 0 | G26: =('Balance Sheet'!H58-'Balance Sheet'!G58) -> 0 | H26: =('Balance Sheet'!I58-'Balance Sheet'!H58) -> 39157984 | I26: =('Balance Sheet'!J58-'Balance Sheet'!I58) -> 0 | J26: =('Balance Sheet'!K58-'Balance Sheet'!J58) -> -7831596.8
A28: Lưu chuyển tiền thuần từ hoạt động tài chính | C28: 8100000 | D28: 7300000 | E28: 0 | F28: =SUM(F25:F27) -> 40464671 | G28: =SUM(G25:G27) -> 0 | H28: =SUM(H25:H27) -> 39157984 | I28: =SUM(I25:I27) -> 0 | J28: =SUM(J25:J27) -> -7831596.8
A30: Số dư tiền mặt đầu kỳ | C30: 910000 | D30: 43988.8 | E30: 1735532.6 | F30: =E34 -> 2933481.8 | G30: =F34 -> 38400238 | H30: =G34 -> 36454184 | I30: =H34 -> 21617752 | J30: =I34 -> 14952947
A32: Biến động tiền mặt trong kỳ | C32: -866011.2 | D32: 1691543.8 | E32: 1197949.2 | F32: =SUM(F17,F22,F28) -> 35466756 | G32: =SUM(G17,G22,G28) -> -1946053.7 | H32: =SUM(H17,H22,H28) -> -14836432 | I32: =SUM(I17,I22,I28) -> -6664804.2 | J32: =SUM(J17,J22,J28) -> -2329730.5
A34: Số dư tiền mặt cuối kỳ | C34: 43988.8 | D34: 1735532.6 | E34: 2933481.8 | F34: =SUM(F32,F30) -> 38400238 | G34: =SUM(G32,G30) -> 36454184 | H34: =SUM(H32,H30) -> 21617752 | I34: =SUM(I32,I30) -> 14952947 | J34: =SUM(J32,J30) -> 12623217

Sheet Discount rate
A1: Discount rate calculation
A2: Beta | B2: =B22 -> 1.5006496 | D2: Chi phí vốn CSH | E2: =B3+B2*(B4-B3) -> 0.16788282
A3: Risk-free rate | B3: =B12 -> 0.04588 | D3: Chi phí vốn nợ (sau thuế) | E3: =B14*(1-Assumption!B13) -> 0.08
A4: Market return | B4: =B23 -> 0.12718 | D4: WACC | E4: =(B6*E2+B7*E3)/B8 -> 0.14130984
A6: Vốn CSH | B6: ='Balance Sheet'!I73 -> 94043843
A7: Nợ vay dài hạn | B7: =SUM('Balance Sheet'!I58,'Balance Sheet'!I45) -> 40760584
A8: Total | B8: =SUM(B6:B7) -> 1.3480443e+08
A11: CƠ SỞ TÍNH CHI PHÍ VỐN | C11: Nguồn / lý do
A12: Lợi suất phi rủi ro Rf | B12: 0.04588 | C12: Nguồn: lợi suất TPCP Việt Nam kỳ hạn 10 năm ngày 01/10/2026 = 4,588% https://vn.investing.com/rates-bonds/vietnam-10-year-bond-yield-historical-data
A13: ERP thị trường phát triển | B13: 0.0423 | C13: Nguồn: Damodaran (01/2026) – ERP thị trường trưởng thành 4,23% https://pages.stern.nyu.edu/~adamodar/New_Home_Page/datafile/ctryprem.html
A14: Lãi suất vay trước thuế (Kd) | B14: 0.1 | C14: Lý do: lãi suất cho vay VND 8,1–10,5%/năm (6/2026); DN nhỏ vay ở nửa trên khung → 10%. Nguồn: NHNN (2026), Mục 3.1.3.
A15: Phần bù rủi ro quốc gia Việt Nam (CRP) | B15: 0.039 | C15: ƯỚC TÍNH: Moody's Ba2 (triển vọng tích cực từ 5/2026); chênh lệch vỡ nợ Ba2 ~2,9% × hệ số biến động cổ phiếu/trái phiếu ~1,35 (phương pháp Damodaran). Nguồn: Moody's (2026); Damodaran (2026). https://pages.stern.nyu.edu/~adamodar/New_Home_Page/datafile/ctryprem.html
A16: ERP Việt Nam = ERP phát triển + CRP | B16: =SUM(B13,B15) -> 0.0813
A17: Beta không đòn bẩy ngành bao bì (βu) | B17: 0.78 | C17: Nguồn: Damodaran (01/2026) – beta không đòn bẩy ngành Packaging & Container 0,78 https://pages.stern.nyu.edu/~adamodar/New_Home_Page/datafile/Betas.html
A18: D/E mục tiêu (BCĐKT dự phóng 2028, sau huy động) | B18: =B7/B6 -> 0.43342108 | C18: Công thức: D/E theo BCĐKT dự phóng cuối 2028 – năm đầu tư lớn (sau huy động vốn cổ phần và khoản vay trung hạn).
A19: Thuế suất | B19: =Assumption!B13 -> 0.2 | C19: Nguồn: Luật Thuế TNDN 67/2025/QH15 (20%).
A20: Beta có đòn bẩy = βu × [1 + (1 − t) × D/E] | B20: =B17*(1+(1-B19)*B18) -> 1.0504548
A21: Hệ số tương quan ρ (NĐT VC đa dạng hóa một phần) | B21: 0.7 | C21: Công thức: beta tổng = beta có đòn bẩy / ρ (B23 = B21/B22), trong đó ρ là hệ số tương quan giữa danh mục của nhà đầu tư VC và thị trường. ρ = 0,7 vì quỹ VC nắm 20–30 khoản đầu tư nên chỉ đa dạng hóa một phần. Nguồn: Damodaran (2009), Valuing Young, Start-up and Growth Companies.
A22: Beta điều chỉnh cho startup (total beta = β / ρ) | B22: =B20/B21 -> 1.5006496
A23: Lợi suất thị trường kỳ vọng = Rf + ERP Việt Nam | B23: =SUM(B12,B16) -> 0.12718

Sheet Assumption
A1: Assumption | B1: ='Income Statement'!D2 -> 2025 | C1: =B1+1 -> 2026 | D1: =C1+1 -> 2027 | E1: =D1+1 -> 2028 | F1: =E1+1 -> 2029 | G1: =F1+1 -> 2030
A2: % Tăng trưởng doanh thu | B2: ='Income Statement'!D11/'Income Statement'!C11-1 -> 0.53731538 | C2: =Drivers!F40 -> 0.33918962 | D2: =Drivers!G40 -> 0.27911837 | E2: =Drivers!H40 -> 0.23277578 | F2: =Drivers!I40 -> 0.38709493 | G2: =Drivers!J40 -> 0.28448645
A3: GVHB/Doanh thu | B3: ='Income Statement'!D18/'Income Statement'!D11 -> 0.48965893 | C3: =Drivers!F84 -> 0.48244588 | D3: =Drivers!G84 -> 0.48470254 | E3: =Drivers!H84 -> 0.49330443 | F3: =Drivers!I84 -> 0.54852273 | G3: =Drivers!J84 -> 0.52640661
A4: Tổng CP hoạt động/Doanh thu | B4: ='Income Statement'!D61/'Income Statement'!D11 -> 0.4143787 | C4: =Drivers!F90 -> 0.39753447 | D4: =Drivers!G90 -> 0.38356396 | E4: =Drivers!H90 -> 0.37887349 | F4: =Drivers!I90 -> 0.37869519 | G4: =Drivers!J90 -> 0.35954615
A5: CP Tài chính/Doanh thu | B5: ='Income Statement'!D67/'Income Statement'!D11 -> 0.0029903761 | C5: =Drivers!F131 -> 0.0025168901 | D5: =Drivers!G131 -> 0.0019676757 | E5: =Drivers!H131 -> 0.021096134 | F5: =Drivers!I131 -> 0.02926702 | G5: =Drivers!J131 -> 0.020596082
A6: TSNH (ngoài tiền)/Doanh thu | B6: =('Balance Sheet'!F21-'Balance Sheet'!F6)/'Income Statement'!D11 -> 0.15961986 | C6: =SUM(Drivers!F106,Drivers!F108,Drivers!F110)/Drivers!F39 -> 0.16385016 | D6: =SUM(Drivers!G106,Drivers!G108,Drivers!G110)/Drivers!G39 -> 0.173963 | E6: =SUM(Drivers!H106,Drivers!H108,Drivers!H110)/Drivers!H39 -> 0.18573215 | F6: =SUM(Drivers!I106,Drivers!I108,Drivers!I110)/Drivers!I39 -> 0.2055825 | G6: =SUM(Drivers!J106,Drivers!J108,Drivers!J110)/Drivers!J39 -> 0.1994593
A7: Nợ ngắn hạn (ngoài vay)/Doanh thu | B7: =('Balance Sheet'!F55-'Balance Sheet'!F45)/'Income Statement'!D11 -> 0.0072083497 | C7: =SUM(Drivers!F112,Drivers!F114)/Drivers!F39 -> 0.0094535096 | D7: =SUM(Drivers!G112,Drivers!G114)/Drivers!G39 -> 0.010842683 | E7: =SUM(Drivers!H112,Drivers!H114)/Drivers!H39 -> 0.01317489 | F7: =SUM(Drivers!I112,Drivers!I114)/Drivers!I39 -> 0.01391296 | G7: =SUM(Drivers!J112,Drivers!J114)/Drivers!J39 -> 0.013590127
A8: Hàng tồn kho/TSNH ngoài tiền | B8: ='Balance Sheet'!F9/('Balance Sheet'!F21-'Balance Sheet'!F6) -> 0.49391451 | C8: =Drivers!F106/SUM(Drivers!F106,Drivers!F108,Drivers!F110) -> 0.4548979 | D8: =Drivers!G106/SUM(Drivers!G106,Drivers!G108,Drivers!G110) -> 0.42359023 | E8: =Drivers!H106/SUM(Drivers!H106,Drivers!H108,Drivers!H110) -> 0.40111133 | F8: =Drivers!I106/SUM(Drivers!I106,Drivers!I108,Drivers!I110) -> 0.40563141 | G8: =Drivers!J106/SUM(Drivers!J106,Drivers!J108,Drivers!J110) -> 0.38738488
A9: Khoản phải thu/TSNH ngoài tiền | B9: ='Balance Sheet'!F12/('Balance Sheet'!F21-'Balance Sheet'!F6) -> 0.23292842 | C9: =Drivers!F108/SUM(Drivers!F106,Drivers!F108,Drivers!F110) -> 0.30097662 | D9: =Drivers!G108/SUM(Drivers!G106,Drivers!G108,Drivers!G110) -> 0.34647582 | E9: =Drivers!H108/SUM(Drivers!H106,Drivers!H108,Drivers!H110) -> 0.38352476 | F9: =Drivers!I108/SUM(Drivers!I106,Drivers!I108,Drivers!I110) -> 0.3997995 | G9: =Drivers!J108/SUM(Drivers!J106,Drivers!J108,Drivers!J110) -> 0.41207295
A10: Khoản phải trả/Nợ NH ngoài vay | B10: ='Balance Sheet'!F38/('Balance Sheet'!F55-'Balance Sheet'!F45) -> 0.76923077 | C10: =Drivers!F112/SUM(Drivers!F112,Drivers!F114) -> 0.78843836 | D10: =Drivers!G112/SUM(Drivers!G112,Drivers!G114) -> 0.81554381 | E10: =Drivers!H112/SUM(Drivers!H112,Drivers!H114) -> 0.84819608 | F10: =Drivers!I112/SUM(Drivers!I112,Drivers!I114) -> 0.85624914 | G10: =Drivers!J112/SUM(Drivers!J112,Drivers!J114) -> 0.85283435
A11: CAPEX/Doanh thu | B11: ='Pro Forma'!B25/'Income Statement'!D11 -> 0.10693778 | C11: =Drivers!F94 -> 0.2 | D11: =Drivers!G94 -> 0.15 | E11: =Drivers!H94 -> 0.65 | F11: =Drivers!I94 -> 0.12 | G11: =Drivers!J94 -> 0.1
A13: Thuế suất thuế TNDN | B13: 0.2 | C13: Nguồn: Luật Thuế TNDN 67/2025/QH15 – thuế suất phổ thông 20%
A14: Tỷ lệ tăng trưởng vĩnh viễn | B14: 0.05 | C14: Lý do: tăng trưởng dài hạn danh nghĩa VND 5%: lạm phát mục tiêu ~4–4,5% cộng tăng trưởng thực thấp; thấp hơn GDP danh nghĩa VN (~10–12%) và thấp hơn Rf + tăng trưởng thực. Nguồn: NHNN, Quốc hội (mục tiêu CPI 2026 ~4,5%); Damodaran (2026). https://congbao.chinhphu.vn/van-ban/nghi-quyet-so-244-2025-qh15-46693.htm
A15: Tỷ lệ khấu hao | B15: 0.12
A16: Tỷ lệ chiết khấu WACC | B16: ='Discount rate'!E4 -> 0.14130984
A17: Lợi nhuận trên vốn đầu tư mới sau 2030 (RONIC) = ROIC 2030E | B17: =DCF!B39 -> 0.12311588
A19: Ghi chú: các tỷ lệ 2026E–2030E là kết quả của mô hình động lực ở sheet Drivers

Sheet Drivers
A1: GIẢ ĐỊNH CHI TIẾT & MÔ HÌNH ĐỘNG LỰC (DRIVERS) – AgriPack
A2: Đơn vị: nghìn đồng
A3: Kịch bản đang chạy (1 = Bear, 2 = Base, 3 = Bull) | C3: 2 | D3: =CHOOSE(C3,"Bear","Base","Bull") -> Base
A6: Chỉ tiêu | B6: Đơn vị / cơ sở | C6: 2023A | D6: 2024A | E6: 2025A | F6: 2026E | G6: 2027E | H6: 2028E | I6: 2029E | J6: 2030E | L6: Giả định
A7: năm (dùng cho công thức) | C7: 2023 | D7: 2024 | E7: 2025 | F7: 2026 | G7: 2027 | H7: 2028 | I7: 2029 | J7: 2030
A8: A. DOANH THU THEO PHÂN KHÚC (Sản lượng × Giá bán)
A9: A1. Bao bì F&B/FMCG (hộp, khay ép khuôn từ bã mía + vỏ trứng)
A10: Giá bán bình quân (ASP) | B10: nghìn đ/sản phẩm | E10: 2.5 | F10: =E10*(1+F11) -> 2.55 | G10: =F10*(1+G11) -> 2.601 | H10: =G10*(1+H11) -> 2.65302 | I10: =H10*(1+I11) -> 2.7060804 | J10: =I10*(1+J11) -> 2.760202 | L10: Lý do: giá 2025 lấy cận dưới khung giá hộp/khay 2.500–4.000đ/cái của nhóm vì doanh thu gồm cả khay nhỏ và đơn hàng sỉ; cao hơn hộp bã mía 500 ml bán lẻ 1.900–2.700đ nhờ ép khuôn theo mẫu. Nguồn: bảng chiến lược giá (Mục 1.2.2), bảng giá hộp 500 ml (Mục 1.1.1)
A11: Tăng giá bán bình quân | B11: %/năm | F11: =CHOOSE($C$3,$C$144,$D$144,$E$144) -> 0.02 | G11: =CHOOSE($C$3,$C$144,$D$144,$E$144) -> 0.02 | H11: =CHOOSE($C$3,$C$144,$D$144,$E$144) -> 0.02 | I11: =CHOOSE($C$3,$C$144,$D$144,$E$144) -> 0.02 | J11: =CHOOSE($C$3,$C$144,$D$144,$E$144) -> 0.02 | L11: Lý do: Base +2%/năm, thấp hơn CPI 8T/2026 (+4,45%) vì khách hàng B2B có sức mạnh đàm phán rất cao và bao bì nhựa rẻ hơn nhiều lần (Mục 3.1.2, 3.2.3); Bear +1%, Bull +2,5%. Nguồn: Cục Thống kê (2026); phân tích ngành của nhóm.
A12: Sản lượng quy đổi | B12: sản phẩm | C12: =C14/$E$10 -> 6022000 | D12: =D14/$E$10 -> 9635200 | E12: =E14/$E$10 -> 15223616 | F12: =E12*(1+F13) -> 20095173 | G12: =F12*(1+G13) -> 25118966 | H12: =G12*(1+H13) -> 30142760 | I12: =H12*(1+I13) -> 40692726 | J12: =I12*(1+J13) -> 50865907 | L12: Lịch sử = doanh thu / ASP 2025 (quy đổi, giả định giá không đổi 2023–25 – do BCTC không công bố sản lượng).
A13: Tăng trưởng sản lượng | B13: % | D13: =D12/C12-1 -> 0.6 | E13: =E12/D12-1 -> 0.58 | F13: =F150*CHOOSE($C$3,$C$143,$D$143,$E$143) -> 0.32 | G13: =G150*CHOOSE($C$3,$C$143,$D$143,$E$143) -> 0.25 | H13: =H150*CHOOSE($C$3,$C$143,$D$143,$E$143) -> 0.2 | I13: =I150*CHOOSE($C$3,$C$143,$D$143,$E$143) -> 0.35 | J13: =J150*CHOOSE($C$3,$C$143,$D$143,$E$143) -> 0.25 | L13: Lý do: sản lượng bị giới hạn bởi công suất: 2026 +32% nhờ máy ép bổ sung (CAPEX 20% DT); 2027 +25% khi khai thác tối đa nhà máy hiện hữu; 2028 +20% vì nhà máy mới đang xây (đầu tư lớn theo đề bài); 2029 +35% khi 2 dây chuyền mới chạy; 2030 +25%. Lịch sử +60% (2024), +58% (2025). Nguồn: BCTC 2023–2025; giả định của nhóm.
A14: Doanh thu F&B/FMCG | B14: nghìn đồng | C14: ='Income Statement'!B4 -> 15055000 | D14: ='Income Statement'!C4 -> 24088000 | E14: ='Income Statement'!D4 -> 38059040 | F14: =F12*F10 -> 51242691 | G14: =G12*G10 -> 65334432 | H14: =H12*H10 -> 79969344 | I14: =I12*I10 -> 1.1011779e+08 | J14: =J12*J10 -> 1.4040018e+08
A16: A2. Thiết kế & sản xuất khuôn theo mẫu
A17: Giá bình quân/bộ khuôn | B17: nghìn đ/bộ | E17: 20000 | F17: =E17*(1+F18) -> 20400 | G17: =F17*(1+G18) -> 20808 | H17: =G17*(1+H18) -> 21224.16 | I17: =H17*(1+I18) -> 21648.643 | J17: =I17*(1+J18) -> 22081.616 | L17: Lý do: ~20 triệu đồng/bộ khuôn, bằng giá tham chiếu khuôn ép bã mía/tre. Nguồn: bảng chiến lược giá (Mục 1.2.2).
A18: Tăng giá | B18: %/năm | F18: =F11 -> 0.02 | G18: =G11 -> 0.02 | H18: =H11 -> 0.02 | I18: =I11 -> 0.02 | J18: =J11 -> 0.02
A19: Số bộ khuôn bàn giao | B19: bộ | C19: =C21/$E$17 -> 151 | D19: =D21/$E$17 -> 211.4 | E19: =E21/$E$17 -> 294.903 | F19: =E19*(1+F20) -> 359.78166 | G19: =F19*(1+G20) -> 431.73799 | H19: =G19*(1+H20) -> 500.81607 | I19: =H19*(1+I20) -> 641.04457 | J19: =I19*(1+J20) -> 769.25348
A20: Tăng trưởng số bộ khuôn | B20: % | D20: =D19/C19-1 -> 0.4 | E20: =E19/D19-1 -> 0.395 | F20: =F151*CHOOSE($C$3,$C$143,$D$143,$E$143) -> 0.22 | G20: =G151*CHOOSE($C$3,$C$143,$D$143,$E$143) -> 0.2 | H20: =H151*CHOOSE($C$3,$C$143,$D$143,$E$143) -> 0.16 | I20: =I151*CHOOSE($C$3,$C$143,$D$143,$E$143) -> 0.28 | J20: =J151*CHOOSE($C$3,$C$143,$D$143,$E$143) -> 0.2 | L20: Lý do: số bộ khuôn gắn với số SKU/khách hàng mới; chậm lại năm 2028 khi nhà máy mới đang xây, tăng nhanh năm 2029 khi có công suất mới và mở thị trường miền Bắc. Lịch sử +40% (2024), +39,5% (2025). Nguồn: BCTC 2023–2025; giả định của nhóm.
A21: Doanh thu thiết kế & khuôn | B21: nghìn đồng | C21: ='Income Statement'!B5 -> 3020000 | D21: ='Income Statement'!C5 -> 4228000 | E21: ='Income Statement'!D5 -> 5898060 | F21: =F19*F17 -> 7339545.9 | G21: =G19*G17 -> 8983604.1 | H21: =H19*H17 -> 10629400 | I21: =I19*I17 -> 13877745 | J21: =J19*J17 -> 16986360
A23: A3. Đệm bảo vệ nội thất / thương mại điện tử
A24: Giá bình quân | B24: nghìn đ/m² | E24: 22.5 | F24: =E24*(1+F25) -> 22.8375 | G24: =F24*(1+G25) -> 23.180062 | H24: =G24*(1+H25) -> 23.527763 | I24: =H24*(1+I25) -> 23.88068 | J24: =I24*(1+J25) -> 24.23889 | L24: Lý do: trung điểm khung 15.000–30.000đ/m² của vật liệu đệm định hình (PE foam) mà sản phẩm thay thế. Nguồn: báo giá PE foam định hình trên thị trường (2026); https://mutxophabac.com/xop-dinh-hinh-nha-san-xuat-gia-re/
A25: Tăng giá | B25: %/năm | F25: =CHOOSE($C$3,$C$145,$D$145,$E$145) -> 0.015 | G25: =CHOOSE($C$3,$C$145,$D$145,$E$145) -> 0.015 | H25: =CHOOSE($C$3,$C$145,$D$145,$E$145) -> 0.015 | I25: =CHOOSE($C$3,$C$145,$D$145,$E$145) -> 0.015 | J25: =CHOOSE($C$3,$C$145,$D$145,$E$145) -> 0.015 | L25: Lý do: đệm bảo vệ cạnh tranh trực tiếp với EPE/PE foam giá rẻ (áp lực thay thế cao, Mục 3.2.6) nên chỉ tăng 1,5%/năm (Base); Bear 0,5%, Bull 2%. Nguồn: phân tích ngành của nhóm.
A26: Diện tích quy đổi | B26: m² | C26: =C28/$E$24 -> 67555.556 | D26: =D28/$E$24 -> 101333.33 | E26: =E28/$E$24 -> 121600 | F26: =E26*(1+F27) -> 158080 | G26: =F26*(1+G27) -> 205504 | H26: =G26*(1+H27) -> 263045.12 | I26: =H26*(1+I27) -> 368263.17 | J26: =I26*(1+J27) -> 486107.38
A27: Tăng trưởng diện tích | B27: % | D27: =D26/C26-1 -> 0.5 | E27: =E26/D26-1 -> 0.2 | F27: =F152*CHOOSE($C$3,$C$143,$D$143,$E$143) -> 0.3 | G27: =G152*CHOOSE($C$3,$C$143,$D$143,$E$143) -> 0.3 | H27: =H152*CHOOSE($C$3,$C$143,$D$143,$E$143) -> 0.28 | I27: =I152*CHOOSE($C$3,$C$143,$D$143,$E$143) -> 0.4 | J27: =J152*CHOOSE($C$3,$C$143,$D$143,$E$143) -> 0.32 | L27: Lý do: bám theo tăng trưởng TMĐT ~18%/năm và khách hàng nội thất xuất khẩu; năm 2029 +40% nhờ công suất mới. Nguồn: Mục 3.2.2; BCTC 2023–2025.
A28: Doanh thu nội thất/TMĐT | B28: nghìn đồng | C28: ='Income Statement'!B6 -> 1520000 | D28: ='Income Statement'!C6 -> 2280000 | E28: ='Income Statement'!D6 -> 2736000 | F28: =F26*F24 -> 3610152 | G28: =G26*G24 -> 4763595.6 | H28: =H26*H24 -> 6188863.4 | I28: =I26*I24 -> 8794374.8 | J28: =J26*J24 -> 11782703
A30: A4. Đệm bảo vệ thiết bị, linh kiện điện tử
A31: Giá bình quân | B31: nghìn đ/m² | E31: 40 | F31: =E31*(1+F32) -> 40.6 | G31: =F31*(1+G32) -> 41.209 | H31: =G31*(1+H32) -> 41.827135 | I31: =H31*(1+I32) -> 42.454542 | J31: =I31*(1+J32) -> 43.09136 | L31: Lý do: trung điểm khung 25.000–55.000đ/m² của khay EPE/EPE chống tĩnh điện mà sản phẩm thay thế. Nguồn: báo giá khay EPE trên thị trường (2026)
A32: Tăng giá | B32: %/năm | F32: =F25 -> 0.015 | G32: =G25 -> 0.015 | H32: =H25 -> 0.015 | I32: =I25 -> 0.015 | J32: =J25 -> 0.015
A33: Diện tích quy đổi | B33: m² | C33: =C35/$E$31 -> 0 | D33: =D35/$E$31 -> 14150 | E33: =E35/$E$31 -> 29715 | F33: =E33*(1+F34) -> 47544 | G33: =F33*(1+G34) -> 71316 | H33: =G33*(1+H34) -> 103408.2 | I33: =H33*(1+I34) -> 175793.94 | J33: =I33*(1+J34) -> 254901.21
A34: Tăng trưởng diện tích | B34: % | E34: =E33/D33-1 -> 1.1 | F34: =F153*CHOOSE($C$3,$C$143,$D$143,$E$143) -> 0.6 | G34: =G153*CHOOSE($C$3,$C$143,$D$143,$E$143) -> 0.5 | H34: =H153*CHOOSE($C$3,$C$143,$D$143,$E$143) -> 0.45 | I34: =I153*CHOOSE($C$3,$C$143,$D$143,$E$143) -> 0.7 | J34: =J153*CHOOSE($C$3,$C$143,$D$143,$E$143) -> 0.45 | L34: Lý do: nền nhỏ (1,2 tỷ đồng năm 2025); thay thế khay EPS/EPE cho khách hàng FDI điện tử khi chuỗi cung ứng xuất khẩu yêu cầu xanh hóa.
A35: Doanh thu điện tử | B35: nghìn đồng | C35: ='Income Statement'!B7 -> 0 | D35: ='Income Statement'!C7 -> 566000 | E35: ='Income Statement'!D7 -> 1188600 | F35: =F33*F31 -> 1930286.4 | G35: =G33*G31 -> 2938861 | H35: =H33*H31 -> 4325268.7 | I35: =I33*I31 -> 7463251.2 | J35: =J33*J31 -> 10984040
A37: Tổng doanh thu gộp | B37: nghìn đồng | C37: =SUM(C14,C21,C28,C35) -> 19595000 | D37: =SUM(D14,D21,D28,D35) -> 31162000 | E37: =SUM(E14,E21,E28,E35) -> 47881700 | F37: =SUM(F14,F21,F28,F35) -> 64122676 | G37: =SUM(G14,G21,G28,G35) -> 82020492 | H37: =SUM(H14,H21,H28,H35) -> 1.0111288e+08 | I37: =SUM(I14,I21,I28,I35) -> 1.4025316e+08 | J37: =SUM(J14,J21,J28,J35) -> 1.8015328e+08
A38: Khoản giảm trừ / doanh thu gộp | B38: % | C38: =-'Income Statement'!B9/C37 -> 0.008 | D38: =-'Income Statement'!C9/D37 -> 0.0075 | E38: =-'Income Statement'!D9/E37 -> 0.007 | F38: 0.007 | G38: 0.007 | H38: 0.007 | I38: 0.007 | J38: 0.007 | L38: Lý do: giữ mức 2025 (0,70% doanh thu gộp), xu hướng giảm từ 0,80% (2023). Nguồn: BCTC 2023–2025
A39: Doanh thu thuần | B39: nghìn đồng | C39: ='Income Statement'!B11 -> 19438240 | D39: ='Income Statement'!C11 -> 30928285 | E39: ='Income Statement'!D11 -> 47546528 | F39: =F37*(1-F38) -> 63673817 | G39: =G37*(1-G38) -> 81446349 | H39: =H37*(1-H38) -> 1.0040509e+08 | I39: =I37*(1-I38) -> 1.3927139e+08 | J39: =J37*(1-J38) -> 1.7889221e+08
A40: Tăng trưởng doanh thu thuần | B40: % | D40: =D39/C39-1 -> 0.59110521 | E40: =E39/D39-1 -> 0.53731538 | F40: =F39/E39-1 -> 0.33918962 | G40: =G39/F39-1 -> 0.27911837 | H40: =H39/G39-1 -> 0.23277578 | I40: =I39/H39-1 -> 0.38709493 | J40: =J39/I39-1 -> 0.28448645
A41: Tỷ trọng F&B/FMCG trong doanh thu gộp | B41: % | C41: =C14/C37 -> 0.76830824 | D41: =D14/D37 -> 0.77299275 | E41: =E14/E37 -> 0.79485565 | F41: =F14/F37 -> 0.79913527 | G41: =G14/G37 -> 0.79656229 | H41: =H14/H37 -> 0.79089179 | I41: =I14/I37 -> 0.78513588 | J41: =J14/J37 -> 0.77933733
A43: A5. Kiểm tra công suất (vòng quay tài sản) & thị phần ngầm định
A44: Nguyên giá TSCĐ bình quân | B44: nghìn đồng | C44: =SUM('Balance Sheet'!C27:C29,C97)/2 -> 17289500 | D44: =SUM(C97:D97)/2 -> 22946800 | E44: =SUM(D97:E97)/2 -> 28641860 | F44: =SUM(E97:F97)/2 -> 37551502 | G44: =SUM(F97:G97)/2 -> 50027360 | H44: =SUM(G97:H97)/2 -> 88767489 | I44: =SUM(H97:I97)/2 -> 1.2975543e+08 | J44: =SUM(I97:J97)/2 -> 1.4705632e+08
A45: Vòng quay nguyên giá TSCĐ (DT thuần / NG bình quân) | B45: lần | C45: =C39/C44 -> 1.1242801 | D45: =D39/D44 -> 1.3478256 | E45: =E39/E44 -> 1.6600363 | F45: =F39/F44 -> 1.6956397 | G45: =G39/G44 -> 1.6280361 | H45: =H39/H44 -> 1.131102 | I45: =I39/I44 -> 1.0733377 | J45: =J39/J44 -> 1.2164877 | L45: Vòng quay 2025 = 1,66x. Nếu vòng quay dự phóng < 2025 → còn công suất trống (không cần CAPEX lớn tiếp theo); nếu >> 2025 → dự báo vượt công suất.
A46: Tỷ giá USD/VND bình quân | B46: VND/USD | E46: 26000 | F46: 26300 | G46: =F46*(1+0.02) -> 26826 | H46: =G46*(1+0.02) -> 27362.52 | I46: =H46*(1+0.02) -> 27909.77 | J46: =I46*(1+0.02) -> 28467.966 | L46: Lý do: dùng để quy đổi doanh thu sang USD khi so với TAM/SAM của IMARC. 2025: 26.000; 2026: 26.300; sau đó VND mất giá 2%/năm. Nguồn: Vietcombank (tỷ giá bán ra); MBS Research dự báo 26.800–27.000 cuối 2026 (Mục 3.1.4).
A47: Doanh thu F&B/FMCG quy USD | B47: triệu USD | E47: =E14*1000/E46/1000000 -> 1.4638092 | F47: =F14*1000/F46/1000000 -> 1.9483913 | G47: =G14*1000/G46/1000000 -> 2.4354891 | H47: =H14*1000/H46/1000000 -> 2.922587 | I47: =I14*1000/I46/1000000 -> 3.9454924 | J47: =J14*1000/J46/1000000 -> 4.9318655
...

Sheet Pro Forma
A1: Báo cáo kết quả hoạt động kinh doanh (dự kiến) 5 năm
B2: 0 | C2: 1 | D2: 2 | E2: 3 | F2: 4 | G2: 5
B3: ='Income Statement'!D2 -> 2025 | C3: =B3+1 -> 2026 | D3: =C3+1 -> 2027 | E3: =D3+1 -> 2028 | F3: =E3+1 -> 2029 | G3: =F3+1 -> 2030
A4: Doanh thu | B4: ='Income Statement'!D11 -> 47546528 | C4: =B4*(1+Assumption!C2) -> 63673817 | D4: =C4*(1+Assumption!D2) -> 81446349 | E4: =D4*(1+Assumption!E2) -> 1.0040509e+08 | F4: =E4*(1+Assumption!F2) -> 1.3927139e+08 | G4: =F4*(1+Assumption!G2) -> 1.7889221e+08
A5: Giá vốn hàng bán (gồm 70% tiền lương, 90% khấu hao) | B5: ='Income Statement'!D18 -> 23281582 | C5: =C4*Assumption!C3 -> 30719170 | D5: =D4*Assumption!D3 -> 39477252 | E5: =E4*Assumption!E3 -> 49530274 | F5: =F4*Assumption!F3 -> 76393522 | G5: =G4*Assumption!G3 -> 94170042
A6: Lợi nhuận gộp | B6: =B4-B5 -> 24264946 | C6: =C4-C5 -> 32954647 | D6: =D4-D5 -> 41969097 | E6: =E4-E5 -> 50874812 | F6: =F4-F5 -> 62877865 | G6: =G4-G5 -> 84722167
A7: Chi phí bán hàng & QLDN (gồm 30% tiền lương, 10% khấu hao) | B7: ='Income Statement'!D61 -> 19702269 | C7: =C4*Assumption!C4 -> 25312537 | D7: =D4*Assumption!D4 -> 31239884 | E7: =E4*Assumption!E4 -> 38040826 | F7: =F4*Assumption!F4 -> 52741404 | G7: =G4*Assumption!G4 -> 64320006
A8: Chi phí thuê cửa hàng | B8: 0 | C8: 0 | D8: 0 | E8: 0 | F8: 0 | G8: 0
A9: Khấu hao (đã phân bổ vào GVHB và CPBH & QLDN) | B9: ='Income Statement'!D69 -> 3131952 | C9: =Assumption!$B$15*B22 -> 3742094.4 | D9: =Assumption!$B$15*C22 -> 5270266 | E9: =Assumption!$B$15*D22 -> 6736300.3 | F9: =Assumption!$B$15*E22 -> 14567897 | G9: =Assumption!$B$15*F22 -> 16573405
A10: Lợi nhuận trước thuế và lãi vay (EBIT) | B10: =B6-B7-B8 -> 4562677.2 | C10: =C6-C7-C8 -> 7642109.6 | D10: =D6-D7-D8 -> 10729213 | E10: =E6-E7-E8 -> 12833987 | F10: =F6-F7-F8 -> 10136460 | G10: =G6-G7-G8 -> 20402161
A11: Chi phí tài chính | B11: ='Income Statement'!D67 -> 142182 | C11: =C4*Assumption!C5 -> 160260 | D11: =D4*Assumption!D5 -> 160260 | E11: =E4*Assumption!E5 -> 2118159.2 | F11: =F4*Assumption!F5 -> 4076058.4 | G11: =G4*Assumption!G5 -> 3684478.5
A12: Lợi nhuận trước thuế | B12: =B10-B11 -> 4420495.2 | C12: =C10-C11 -> 7481849.6 | D12: =D10-D11 -> 10568953 | E12: =E10-E11 -> 10715827 | F12: =F10-F11 -> 6060401.9 | G12: =G10-G11 -> 16717683
A13: Thuế TNDN | B13: 0 | C13: =Drivers!F138 -> 902709.76 | D13: =Drivers!G138 -> 2113790.6 | E13: =Drivers!H138 -> 2143165.5 | F13: =Drivers!I138 -> 1212080.4 | G13: =Drivers!J138 -> 3343536.5
A14: Lợi nhuận sau thuế | B14: =B12-B13 -> 4420495.2 | C14: =C12-C13 -> 6579139.9 | D14: =D12-D13 -> 8455162.4 | E14: =E12-E13 -> 8572661.9 | F14: =F12-F13 -> 4848321.5 | G14: =G12-G13 -> 13374146
A17: Tính toán chi tiết:
A19: Chi phí đầu tư tài sản cố định (CAPEX)
B21: =B3 -> 2025 | C21: =B21+1 -> 2026 | D21: =C21+1 -> 2027 | E21: =D21+1 -> 2028 | F21: =E21+1 -> 2029 | G21: =F21+1 -> 2030
A22: Tài sản dài hạn | B22: =SUM('Balance Sheet'!F27:F29) -> 31184120 | C22: =SUM(B22,C25) -> 43918883 | D22: =SUM(C22,D25) -> 56135836 | E22: =SUM(D22,E25) -> 1.2139914e+08 | F22: =SUM(E22,F25) -> 1.3811171e+08 | G22: =SUM(F22,G25) -> 1.5600093e+08
A23: Khấu hao lũy kế | B23: ='Balance Sheet'!F24 -> 9789432 | C23: =SUM(B23,C9) -> 13531526 | D23: =SUM(C23,D9) -> 18801792 | E23: =SUM(D23,E9) -> 25538093 | F23: =SUM(E23,F9) -> 40105990 | G23: =SUM(F23,G9) -> 56679395
A24: Tổng tài sản dài hạn (ròng) | B24: =B22-B23 -> 21394688 | C24: =C22-C23 -> 30387357 | D24: =D22-D23 -> 37334043 | E24: =E22-E23 -> 95861049 | F24: =F22-F23 -> 98005719 | G24: =G22-G23 -> 99321535
A25: CAPEX | B25: =B22-SUM('Balance Sheet'!E27:E29) -> 5084520 | C25: =C4*Assumption!C11 -> 12734763 | D25: =D4*Assumption!D11 -> 12216952 | E25: =E4*Assumption!E11 -> 65263306 | F25: =F4*Assumption!F11 -> 16712566 | G25: =G4*Assumption!G11 -> 17889221
A28: Điều chỉnh Vốn lưu động ròng
B30: =B21 -> 2025 | C30: =B30+1 -> 2026 | D30: =C30+1 -> 2027 | E30: =D30+1 -> 2028 | F30: =E30+1 -> 2029 | G30: =F30+1 -> 2030
A31: Tài sản ngắn hạn (ngoài tiền) | B31: ='Balance Sheet'!F21-'Balance Sheet'!F6 -> 7589370 | C31: =C4*Assumption!C6 -> 10432965 | D31: =D4*Assumption!D6 -> 14168651 | E31: =E4*Assumption!E6 -> 18648452 | F31: =F4*Assumption!F6 -> 28631760 | G31: =G4*Assumption!G6 -> 35681714
A32: Hàng tồn kho | B32: ='Balance Sheet'!F9 -> 3748500 | C32: =C31*Assumption!C8 -> 4745934 | D32: =D31*Assumption!D8 -> 6001702.1 | E32: =E31*Assumption!E8 -> 7480105.5 | F32: =F31*Assumption!F8 -> 11613941 | G32: =G31*Assumption!G8 -> 13822557
A33: Khoản phải thu ngắn hạn | B33: ='Balance Sheet'!F12 -> 1767780 | C33: =C31*Assumption!C9 -> 3140078.6 | D33: =D31*Assumption!D9 -> 4909095 | E33: =E31*Assumption!E9 -> 7152143.2 | F33: =F31*Assumption!F9 -> 11446963 | G33: =G31*Assumption!G9 -> 14703469
A34: Nợ ngắn hạn (ngoài vay) | B34: ='Balance Sheet'!F55-'Balance Sheet'!F45 -> 342732 | C34: =C4*Assumption!C7 -> 601941.04 | D34: =D4*Assumption!D7 -> 883096.95 | E34: =E4*Assumption!E7 -> 1322826 | F34: =F4*Assumption!F7 -> 1937677.2 | G34: =G4*Assumption!G7 -> 2431167.9
A35: Khoản phải trả ngắn hạn | B35: ='Balance Sheet'!F38 -> 263640 | C35: =C34*Assumption!C10 -> 474593.4 | D35: =D34*Assumption!D10 -> 720204.25 | E35: =E34*Assumption!E10 -> 1122015.8 | F35: =F34*Assumption!F10 -> 1659134.4 | G35: =G34*Assumption!G10 -> 2073383.5
A36: Vốn lưu động hoạt động ròng (TSNH ngoài tiền − Nợ NH ngoài vay) | B36: =B31-B34 -> 7246638 | C36: =C31-C34 -> 9831024.3 | D36: =D31-D34 -> 13285554 | E36: =E31-E34 -> 17325626 | F36: =F31-F34 -> 26694083 | G36: =G31-G34 -> 33250546
A37: Biến động VLĐ ròng | C37: =C36-B36 -> 2584386.3 | D37: =D36-C36 -> 3454529.8 | E37: =E36-D36 -> 4040072 | F37: =F36-E36 -> 9368456.4 | G37: =G36-F36 -> 6556463.9
A40: Xác định nhu cầu vốn
A41: Cash Flow Statment Pro-forma
B42: 0 | C42: 1 | D42: 2 | E42: 3 | F42: 4 | G42: 5
B43: =B30 -> 2025 | C43: =B43+1 -> 2026 | D43: =C43+1 -> 2027 | E43: =D43+1 -> 2028 | F43: =E43+1 -> 2029 | G43: =F43+1 -> 2030
A44: ='Cash Flow Statement'!A3 -> Hoạt động kinh doanh
A45: ='Cash Flow Statement'!B4 -> Lợi nhuận sau thuế | B45: =B14 -> 4420495.2 | C45: =C14 -> 6579139.9 | D45: =D14 -> 8455162.4 | E45: =E14 -> 8572661.9 | F45: =F14 -> 4848321.5 | G45: =G14 -> 13374146
A46: ='Cash Flow Statement'!B6 -> Khấu hao | B46: =B9 -> 3131952 | C46: =C9 -> 3742094.4 | D46: =D9 -> 5270266 | E46: =E9 -> 6736300.3 | F46: =F9 -> 14567897 | G46: =G9 -> 16573405
A47: Biến động TSNH | B47: =SUM('Cash Flow Statement'!E9:E11) -> -1343670 | C47: =B31-C31 -> -2843595.4 | D47: =C31-D31 -> -3735685.7 | E47: =D31-E31 -> -4479801.1 | F47: =E31-F31 -> -9983307.6 | G47: =F31-G31 -> -7049954.6
A48: Biến động Nợ NH | B48: =SUM('Cash Flow Statement'!E13:E15) -> 73692 | C48: =C34-B34 -> 259209.04 | D48: =D34-C34 -> 281155.91 | E48: =E34-D34 -> 439729.05 | F48: =F34-E34 -> 614851.2 | G48: =G34-F34 -> 493490.72
A49: Lưu chuyển tiền thuần từ HĐKD | B49: =SUM(B45:B48) -> 6282469.2 | C49: =SUM(C45:C48) -> 7736847.9 | D49: =SUM(D45:D48) -> 10270899 | E49: =SUM(E45:E48) -> 11268890 | F49: =SUM(F45:F48) -> 10047762 | G49: =SUM(G45:G48) -> 23391087
...

Sheet DCF
A1: Dòng tiền tự do (FCFF) của doanh nghiệp
A3: Số năm chiết khấu từ t0 = 01/10/2026 (B3 = phần năm 2026 còn lại) | B3: 0.25 | C3: =B3 -> 0.25 | D3: =C3+1 -> 1.25 | E3: =D3+1 -> 2.25 | F3: =E3+1 -> 3.25 | G3: =F3+1 -> 4.25
B4: ='Income Statement'!D2 -> 2025 | C4: =B4+1 -> 2026 | D4: =C4+1 -> 2027 | E4: =D4+1 -> 2028 | F4: =E4+1 -> 2029 | G4: =F4+1 -> 2030 | H4: =G4+1 -> 2031
A5: Lợi nhuận sau thuế trước lãi vay EBIT*(1-t) | C5: ='Pro Forma'!C10-Drivers!F136*MAX(0,'Pro Forma'!C10-Drivers!F134) -> 6712155.7 | D5: ='Pro Forma'!D10-Drivers!G136*MAX(0,'Pro Forma'!D10-Drivers!G134) -> 8583370.4 | E5: ='Pro Forma'!E10-Drivers!H136*MAX(0,'Pro Forma'!E10-Drivers!H134) -> 10267189 | F5: ='Pro Forma'!F10-Drivers!I136*MAX(0,'Pro Forma'!F10-Drivers!I134) -> 8109168.2 | G5: ='Pro Forma'!G10-Drivers!J136*MAX(0,'Pro Forma'!G10-Drivers!J134) -> 16321729
A6: + Khấu hao | C6: ='Pro Forma'!C9 -> 3742094.4 | D6: ='Pro Forma'!D9 -> 5270266 | E6: ='Pro Forma'!E9 -> 6736300.3 | F6: ='Pro Forma'!F9 -> 14567897 | G6: ='Pro Forma'!G9 -> 16573405
A7: - Điều chỉnh VLĐ | C7: ='Pro Forma'!C37 -> 2584386.3 | D7: ='Pro Forma'!D37 -> 3454529.8 | E7: ='Pro Forma'!E37 -> 4040072 | F7: ='Pro Forma'!F37 -> 9368456.4 | G7: ='Pro Forma'!G37 -> 6556463.9
A8: - CAPEX | C8: ='Pro Forma'!C25 -> 12734763 | D8: ='Pro Forma'!D25 -> 12216952 | E8: ='Pro Forma'!E25 -> 65263306 | F8: ='Pro Forma'!F25 -> 16712566 | G8: ='Pro Forma'!G25 -> 17889221
H9: FCFF 2031 chuẩn hóa
A10: Dòng tiền tự do (FCFF) | C10: =C5+C6-C7-C8 -> -4864899.6 | D10: =D5+D6-D7-D8 -> -1817845.7 | E10: =E5+E6-E7-E8 -> -52299889 | F10: =F5+F6-F7-F8 -> -3403957.5 | G10: =G5+G6-G7-G8 -> 8449449.1 | H10: =G5*(1+Assumption!B14)*(1-Assumption!B14/Assumption!B17) -> 10177781 | I10: FCFF 2031 = NOPAT 2031 × (1 − g/RONIC): phần tái đầu tư chỉ vừa đủ cho tăng trưởng g
A11: Tỷ lệ dòng tiền năm được tính (2026: chỉ quý IV) | C11: =B3 -> 0.25 | D11: 1 | E11: 1 | F11: 1 | G11: 1
A12: Giá trị cuối kỳ tại t=5 = FCFF 2031 / (WACC − g) | G12: =H10/(Assumption!B16-Assumption!B14) -> 1.1146423e+08
A14: Giá trị hiện tại của các dòng tiền | C14: =C10*C11/(1+Assumption!$B$16)^C3 -> -1176692.6 | D14: =D10*D11/(1+Assumption!$B$16)^D3 -> -1540999.8 | E14: =E10*E11/(1+Assumption!$B$16)^E3 -> -38845682 | F14: =F10*F11/(1+Assumption!$B$16)^F3 -> -2215249 | G14: =(G10*G11+G12)/(1+Assumption!$B$16)^G3 -> 68375985
A16: Giá trị doanh nghiệp | C16: =SUM(C14:G14) -> 24597361
A19: Nhu cầu vốn | B19: ='Pro Forma'!B61 -> 40464671
A20: Tỷ lệ nắm giữ | B20: =B19/B21 -> 0.63764628
A21: Post-money value | B21: =SUM(B22,B19) -> 63459433
A22: Pre-money value | B22: =B33 -> 22994761 | D22: Pitch: Kêu gọi | E22: =B19 -> 40464671 | F22: nghìn đồng tương ứng | G22: =B20 -> 0.63764628 | H22: cổ phần.
A26: CẦU NỐI EV → VỐN CSH & KIỂM TRA
A27: PV dòng tiền tự do Q4/2026–2030 | B27: =SUM(C14:F14)+G10*G11/(1+Assumption!B16)^G3 -> -38960663
A28: PV giá trị cuối kỳ | B28: =G12/(1+Assumption!B16)^G3 -> 63558024
A29: Giá trị doanh nghiệp (EV) | B29: =C16 -> 24597361
A30: Tỷ trọng giá trị cuối kỳ / EV | B30: =B28/B29 -> 2.5839367
A31: (+) Tiền mặt ước tính 30/09/2026 = tiền 31/12/2025 + 75% FCFF 2026 (≥ 0) | B31: =MAX(0,'Balance Sheet'!F6+(1-B3)*C10) -> 0
A32: (−) Nợ vay 30/09/2026 (= 31/12/2025; không vay mới trong 2026) | B32: =SUM('Balance Sheet'!F45,'Balance Sheet'!F58) -> 1602600
A33: Giá trị vốn CSH trước gọi vốn (pre-money) | B33: =B29+B31-B32 -> 22994761
A34: EV/EBITDA 2025A ngầm định | B34: =B29/Drivers!E77 -> 3.1966922
A35: EV/EBITDA 2026E ngầm định | B35: =B29/Drivers!F77 -> 2.1606571
A36: P/E 2026E ngầm định (pre-money) | B36: =B33/'Income Statement'!E78 -> 3.4951015
A37: P/B 2025A ngầm định | B37: =B33/'Balance Sheet'!F73 -> 0.76720279
A38: Giá trị cuối kỳ nếu không chuẩn hóa = FCFF 2030 × (1 + g)/(WACC − g) | B38: =G10*(1+Assumption!B14)/(Assumption!B16-Assumption!B14) -> 97162820
A39: ROIC 2030E = NOPAT / (TSCĐ ròng + VLĐ) | B39: =G5/SUM('Pro Forma'!G24,'Pro Forma'!G36) -> 0.12311588
A40: Tỷ lệ tái đầu tư trong giá trị cuối kỳ = g / RONIC | B40: =Assumption!B14/Assumption!B17 -> 0.40612144

Sheet VCM
A1: The VC Method | C1: =DCF!G4 -> 2030
A2: Tỷ lệ chiết khấu có điều chỉnh
A3: Số kỳ | B3: =DCF!G3 -> 4.25 | D3: Nhu cầu vốn | E3: =DCF!B19 -> 40464671
A4: Tỷ lệ thất bại của VC | B4: 0.4 | C4: Giả định: z = 35–45%; lấy 40% (trung điểm). | D4: Giá trị thoái vốn kỳ vọng | E4: =B35 -> 2.0060787e+08
A5: Tỷ lệ chiết khấu (WACC) | B5: ='Discount rate'!E4 -> 0.14130984 | D5: Post-money value | E5: =E4/(1+B7)^B3 -> 68633172
D6: Tỷ lệ sở hữu của NĐT mới | E6: =E3/E5 -> 0.58957892
A7: Tỷ lệ chiết khấu có điều chỉnh p = (1 + r)/(1 − z)^(1/n) − 1 | B7: =(1+B5)/(1-B4)^(1/B3)-1 -> 0.28707326 | D7: Pre-money value | E7: =E5-E3 -> 28168501
D8: Tỷ lệ sở hữu của Founder và NĐT cũ | E8: =1-E6 -> 0.41042108
A11: Pitch: Kêu gọi | B11: =E3 -> 40464671 | C11: nghìn đồng tương ứng | D11: =E6 -> 0.58957892 | E11: cổ phần.
A15: Tỷ lệ thất bại theo giai đoạn đầu tư VC (đề bài) | B15: Thấp | C15: Cao | D15: Trung điểm
A16: Ươm mầm | B16: 0.65 | C16: 0.8 | D16: =AVERAGE(B16:C16) -> 0.725
A17: Thử nghiệm | B17: 0.5 | C17: 0.65 | D17: =AVERAGE(B17:C17) -> 0.575
A18: Đầu tăng trưởng | B18: 0.35 | C18: 0.45 | D18: =AVERAGE(B18:C18) -> 0.4
A19: Cuối tăng trưởng | B19: 0.2 | C19: 0.3 | D19: =AVERAGE(B19:C19) -> 0.25
A21: Giai đoạn của AgriPack | B21: Đầu tăng trưởng | C21: Lý do: doanh thu 47,5 tỷ, tăng 54–59%/năm, LNST và FCF vừa dương năm 2025, D/E 6,5%. Nguồn: kết luận Mục 2.
A23: GIÁ TRỊ THOÁI VỐN CUỐI 2030
A24: LNST 2030E | B24: ='Income Statement'!I78 -> 13374146
A25: P/E thoát vốn | B25: 9.4 | C25: Lý do: P/E ngành Containers & Packaging (ICB cấp 4) năm 2026: 9,43x; trung vị mẫu 14 DN: xem Multiples!G22. Nguồn: FiinX (giá đóng cửa 28/9/2026).
A26: Giá trị vốn CSH theo P/E | B26: =B24*B25 -> 1.2571697e+08
A27: EBITDA 2030E | B27: ='Income Statement'!I80 -> 36975566
A28: EV/EBITDA thoát vốn | B28: 8 | C28: EV/EBITDA ngành Containers & Packaging 2026: 7,99x (2025: 7,5x). Nguồn: FiinX (giá đóng cửa 28/9/2026).
A29: EV theo EV/EBITDA | B29: =B27*B28 -> 2.9580453e+08
A30: (+) Tiền mặt 2030E | B30: ='Balance Sheet'!K6 -> 12623217
A31: (−) Nợ vay 2030E | B31: =SUM('Balance Sheet'!K45,'Balance Sheet'!K58) -> 32928987
A32: Giá trị vốn CSH theo EV/EBITDA | B32: =B29+B30-B31 -> 2.7549876e+08
A33: Đối chiếu: giá trị vốn CSH theo DCF tại 2030 (TV + tiền − nợ) | B33: =DCF!G12+B30-B31 -> 91158461
A34: EV/EBITDA ngầm định của P/E thoát vốn | B34: =(B26-B30+B31)/B27 -> 3.9491685
A35: Giá trị thoái vốn sử dụng (bình quân P/E và EV/EBITDA) | B35: =AVERAGE(B26,B32) -> 2.0060787e+08
A37: IRR kỳ vọng của NĐT nếu thành công | B37: =(E4*E6/E3)^(1/B3)-1 -> 0.28707326
A38: IRR kỳ vọng có tính xác suất thất bại (= WACC) | B38: =((1-B4)*E4*E6/E3)^(1/B3)-1 -> 0.14130984

Sheet Multiples
A1: ĐỊNH GIÁ BẰNG BỘI SỐ SO SÁNH (MULTIPLES / COMPARABLES) – AgriPack
A2: Đơn vị: tỷ đồng; bội số: lần. Mẫu so sánh: 16 DN bao bì niêm yết (FiinX, giá đóng cửa 28/9/2026; BCTC quý đến Q2/2026, TTM).
A4: Mã | B4: Sàn | C4: Phân khúc | D4: DT TTM (tỷ) | E4: Biên EBITDA (%) | F4: EV/EBITDA (x) | G4: P/E (x) | H4: Đưa vào mẫu | I4: EV/EBITDA (mẫu) | J4: P/E (mẫu) | K4: Nguồn
A5: DHC | B5: HOSE | C5: Giấy, bao bì carton | D5: 3938 | E5: 18.9 | F5: 6.35 | G5: 7.48 | H5: 1 | I5: =IF(H5=1,F5,"") -> 6.35 | J5: =IF(H5=1,G5,"") -> 7.48 | K5: FiinX: BCTC 4 quý gần nhất đến Q2/2026; giá đóng cửa 28/9/2026
A6: TDP | B6: HOSE | C6: Bao bì nhựa | D6: 5488 | E6: 8.3 | F6: 8.98 | G6: 20.51 | H6: 1 | I6: =IF(H6=1,F6,"") -> 8.98 | J6: =IF(H6=1,G6,"") -> 20.51 | K6: FiinX: BCTC 4 quý gần nhất đến Q2/2026; giá đóng cửa 28/9/2026
A7: AAA | B7: HOSE | C7: Nhựa, nhựa sinh học | D7: 9243 | E7: 14.2 | F7: 3.85 | G7: 5.16 | H7: 1 | I7: =IF(H7=1,F7,"") -> 3.85 | J7: =IF(H7=1,G7,"") -> 5.16 | K7: FiinX: BCTC 4 quý gần nhất đến Q2/2026; giá đóng cửa 28/9/2026
A8: APH | B8: HOSE | C8: Bao bì nhựa (holding) | D8: 9252 | E8: 14 | F8: 5.05 | G8: 6.98 | H8: 1 | I8: =IF(H8=1,F8,"") -> 5.05 | J8: =IF(H8=1,G8,"") -> 6.98 | K8: FiinX: BCTC 4 quý gần nhất đến Q2/2026; giá đóng cửa 28/9/2026
A9: HHP | B9: HOSE | C9: Giấy bao bì | D9: 3112 | E9: 9.3 | F9: 13.71 | G9: 32.9 | H9: 1 | I9: =IF(H9=1,F9,"") -> 13.71 | J9: =IF(H9=1,G9,"") -> 32.9 | K9: FiinX: BCTC 4 quý gần nhất đến Q2/2026; giá đóng cửa 28/9/2026
A10: INN | B10: HNX | C10: Bao bì giấy, in | D10: 1921 | E10: 14.9 | F10: 2.66 | G10: 7.29 | H10: 1 | I10: =IF(H10=1,F10,"") -> 2.66 | J10: =IF(H10=1,G10,"") -> 7.29 | K10: FiinX: BCTC 4 quý gần nhất đến Q2/2026; giá đóng cửa 28/9/2026
A11: ILS | B11: UPCoM | C11: Bao bì khác | D11: 319 | E11: 16.4 | F11: 13.33 | G11: 16.64 | H11: 1 | I11: =IF(H11=1,F11,"") -> 13.33 | J11: =IF(H11=1,G11,"") -> 16.64 | K11: FiinX: BCTC 4 quý gần nhất đến Q2/2026; giá đóng cửa 28/9/2026
A12: TPP | B12: HNX | C12: Bao bì nhựa | D12: 3179 | E12: 15.9 | F12: 3.28 | G12: 2.54 | H12: 1 | I12: =IF(H12=1,F12,"") -> 3.28 | J12: =IF(H12=1,G12,"") -> 2.54 | K12: FiinX: BCTC 4 quý gần nhất đến Q2/2026; giá đóng cửa 28/9/2026
A13: MCP | B13: HOSE | C13: Bao bì kim loại, in | D13: 431 | E13: 2.9 | F13: 36.45 | G13: 84.23 | H13: 0 | I13: =IF(H13=1,F13,"") | J13: =IF(H13=1,G13,"") | K13: FiinX (28/9/2026); loại khỏi mẫu – xem ghi chú dòng 2
A14: PBT | B14: UPCoM | C14: Thương mại vật tư bao bì | D14: 2042 | E14: 1.9 | F14: 0.04 | G14: 9.97 | H14: 0 | I14: =IF(H14=1,F14,"") | J14: =IF(H14=1,G14,"") | K14: FiinX (28/9/2026); loại khỏi mẫu – xem ghi chú dòng 2
A15: TPC | B15: HOSE | C15: Màng, túi nhựa | D15: 490 | E15: 7 | F15: 4.21 | G15: 20.41 | H15: 1 | I15: =IF(H15=1,F15,"") -> 4.21 | J15: =IF(H15=1,G15,"") -> 20.41 | K15: FiinX: BCTC 4 quý gần nhất đến Q2/2026; giá đóng cửa 28/9/2026
A16: VBC | B16: HNX | C16: Bao bì nhựa | D16: 913 | F16: 4.17 | G16: 4.85 | H16: 1 | I16: =IF(H16=1,F16,"") -> 4.17 | J16: =IF(H16=1,G16,"") -> 4.85 | K16: FiinX: BCTC 4 quý gần nhất đến Q2/2026; giá đóng cửa 28/9/2026
A17: BBS | B17: HNX | C17: Bao bì giấy, bao xi măng | D17: 484 | E17: 6.5 | F17: 5.5 | G17: 9.19 | H17: 1 | I17: =IF(H17=1,F17,"") -> 5.5 | J17: =IF(H17=1,G17,"") -> 9.19 | K17: FiinX: BCTC 4 quý gần nhất đến Q2/2026; giá đóng cửa 28/9/2026
A18: STP | B18: HNX | C18: Bao bì giấy | D18: 212 | F18: 2.96 | G18: 6.65 | H18: 1 | I18: =IF(H18=1,F18,"") -> 2.96 | J18: =IF(H18=1,G18,"") -> 6.65 | K18: FiinX: BCTC 4 quý gần nhất đến Q2/2026; giá đóng cửa 28/9/2026
A19: PBP | B19: HNX | C19: Bao bì PP | D19: 372 | E19: 5.3 | F19: 2.06 | G19: 6.46 | H19: 1 | I19: =IF(H19=1,F19,"") -> 2.06 | J19: =IF(H19=1,G19,"") -> 6.46 | K19: FiinX: BCTC 4 quý gần nhất đến Q2/2026; giá đóng cửa 28/9/2026
A20: PMP | B20: HNX | C20: Bao bì PP | D20: 746 | E20: 4 | F20: 5.4 | G20: 5.53 | H20: 1 | I20: =IF(H20=1,F20,"") -> 5.4 | J20: =IF(H20=1,G20,"") -> 5.53 | K20: FiinX: BCTC 4 quý gần nhất đến Q2/2026; giá đóng cửa 28/9/2026
A22: Trung vị các DN trong mẫu | F22: =MEDIAN(I5:I20) -> 4.63 | G22: =MEDIAN(J5:J20) -> 7.135 | H22: =SUM(H5:H20) -> 14
A23: Bình quân ngành Containers & Packaging 2026 (FiinX, ICB cấp 4) | F23: 7.99 | G23: 9.43 | H23: Nguồn: FiinX – bình quân ngành Containers & Packaging (ICB cấp 4), cột 2026.
