Workbook

Sheet Hướng dẫn
B4: Three Statement Model
I6: Năm hiện tại | J6: 2026
C8: LƯU Ý
B9: Model Legend
C11: Ô nhập liệu | D11: ABC | E11: Chỉ nhập dữ liệu vào những ô màu vàng này
C13: Tất cả các ô khác đã được nhập sẵn hàm hoặc là ô chứa dữ liệu cho trước. KHÔNG thay đổi những ô này!
B16: CẤU TRÚC FILE SAU KHI HOÀN THIỆN (Lộc)
B17: Drivers | D17: Mô hình động lực: sản lượng × giá theo 4 phân khúc, chi phí theo dòng, BCKQKD theo chức năng (70/30 tiền lương, 90/10 khấu hao), CAPEX/khấu hao, vốn lưu động, vay, thuế, kịch bản (ô chọn C3, C4). Cột K: nguồn/lý do của từng giả định.
B18: Assumption | D18: Tỷ lệ tổng hợp 2026E–2030E (liên kết từ Drivers) + g, RONIC (nguồn ở cột E).
B19: Pro Forma | D19: KQKD 5 năm, CAPEX, VLĐ, lưu chuyển tiền trước khi huy động vốn, nhu cầu vốn (B61:B63).
B20: IS / BS / CF | D20: Báo cáo tài chính đầy đủ 2023A–2030E; BCKQKD theo chức năng (VAS), EBITDA ghi nhớ ở IS hàng 82; BCĐKT cân (hàng 80).
B21: Discount rate | D21: WACC: Rf = bình quân lợi suất TPCP 10 năm 2016–2025 (bảng A28:D40), ERP Việt Nam, beta ngành → total beta, Kd, cơ cấu vốn mục tiêu; nguồn ở cột C.
B22: DCF / VCM / Multiples | D22: Định giá theo 3 phương pháp: DCF (FCFF), VC Method (thoái vốn 2030, z 40%), bội số EV/EBITDA và P/E của 14 DN bao bì niêm yết (DLOM 30%).
B23: Summary / Sensitivity | D23: Tổng hợp định giá (trọng số 40/40/20), football field, kịch bản, độ nhạy theo nhân tố vĩ mô – ngành (Summary hàng 48–58); bảng độ nhạy tính lại toàn bộ mô hình.
B24: Checks / Chart_Data / Ghi chu | D24: Kiểm tra toàn vẹn; dữ liệu cho từng Fig. của báo cáo; các chỉnh sửa template.

Sheet Investment
A1: Các khoản đầu tư dự kiến 5 năm
B3: Đơn giá (nghìn đồng) | C3: Số lượng | D3: Thành tiền | E3: Tháng | F3: Năm | G3: Thời gian sử dụng | H3: Giá trị còn lại
D4: =SUM(D5:D7) -> 24090000 | F4: ='Cash Flow Statement'!E4+1 -> 2026
A5: Nhà máy sản xuất | B5: 30550000 | C5: 0 | D5: =B5*C5 -> 0 | E5: 10 | G5: 8
A6: Thiết bị sản xuất | B6: 3600000 | C6: 5 | D6: =B6*C6 -> 18000000 | E6: 11 | G6: 5
A7: Xe tải chở hàng | B7: 1218000 | C7: 5 | D7: =B7*C7 -> 6090000 | E7: 11 | G7: 5
D8: =SUM(D9:D10) -> 77100000 | F8: =F4+1 -> 2027
A9: Nhà máy sản xuất | B9: 30550000 | C9: 2 | D9: =B9*C9 -> 61100000 | E9: 10 | G9: 7
A10: Kho hàng | B10: 4000000 | C10: 4 | D10: =B10*C10 -> 16000000 | E10: 5 | G10: 7
D11: =SUM(D12) -> 22640000 | F11: =F8+1 -> 2028 | I11: Đầu tư mạnh tăng trưởng mở rộng KD
A12: Thiết bị sản xuất | B12: 5660000 | C12: 4 | D12: =B12*C12 -> 22640000 | E12: 9 | G12: 5 | I12: CAPEX/Revenue = 60%
D13: =SUM(D14) -> 35220000 | F13: =F11+1 -> 2029
A14: Thiết bị sản xuất | B14: 5870000 | C14: 6 | D14: =B14*C14 -> 35220000 | E14: 4 | G14: 8
D15: =SUM(D16:D17) -> 32460000 | F15: =F13+1 -> 2030
A16: Nâng cấp văn phòng | B16: 8115000 | C16: 4 | D16: =B16*C16 -> 32460000 | E16: 1 | G16: 6

Sheet Income Statement
A1: Income Statement
D3: Đơn vị: Nghìn đồng
B4: ='Hướng dẫn'!J6-3 -> 2023 | C4: =B4+1 -> 2024 | D4: =C4+1 -> 2025 | E4: =D4+1 -> 2026 | F4: =E4+1 -> 2027 | G4: =F4+1 -> 2028 | H4: =G4+1 -> 2029 | I4: =H4+1 -> 2030 | J4: Ngoài kỳ dự phóng 5 năm – không sử dụng
A5: Doanh thu bán hàng
A6: Doanh thu 1 | B6: 15055000 | C6: 24088000 | D6: 38059040 | E6: =Drivers!F14 -> 51242691 | F6: =Drivers!G14 -> 63766405 | G6: =Drivers!H14 -> 87806340 | H6: =Drivers!I14 -> 1.1195308e+08 | I6: =Drivers!J14 -> 1.3360481e+08
A7: Doanh thu 2 | B7: 3020000 | C7: 4228000 | D7: 5898060 | E7: =Drivers!F21 -> 7339545.9 | F7: =Drivers!G21 -> 8833877.4 | G7: =Drivers!H21 -> 11533510 | H7: =Drivers!I21 -> 14117017 | I7: =Drivers!J21 -> 16559261
A8: Doanh thu 3 | B8: 1520000 | C8: 2280000 | D8: 2736000 | E8: =Drivers!F28 -> 3610152 | F8: =Drivers!G28 -> 4763595.6 | G8: =Drivers!H28 -> 6769069.3 | H8: =Drivers!I28 -> 9069199 | I8: =Drivers!J28 -> 11506546
A9: Doanh thu 4 | B9: 0 | C9: 566000 | D9: 1188600 | E9: =Drivers!F35 -> 1930286.4 | F9: =Drivers!G35 -> 2938861 | G9: =Drivers!H35 -> 5071004.7 | H9: =Drivers!I35 -> 7463251.2 | I9: =Drivers!J35 -> 9847760
A11: (-) Khoản giảm trừ | B11: -156760 | C11: -233715 | D11: -335171.9 | E11: =-SUM(E6:E9)*Drivers!F38 -> -448858.73 | F11: =-SUM(F6:F9)*Drivers!G38 -> -562119.17 | G11: =-SUM(G6:G9)*Drivers!H38 -> -778259.47 | H11: =-SUM(H6:H9)*Drivers!I38 -> -998217.85 | I11: =-SUM(I6:I9)*Drivers!J38 -> -1200628.6
A13: Doanh thu thuần | B13: 19438240 | C13: 30928285 | D13: 47546528 | E13: =SUM(E6:E12) -> 63673817 | F13: =SUM(F6:F12) -> 79740620 | G13: =SUM(G6:G12) -> 1.1040166e+08 | H13: =SUM(H6:H12) -> 1.4160433e+08 | I13: =SUM(I6:I12) -> 1.7031775e+08
A15: Giá vốn hàng bán
A16: Chi phí biến đổi | B16: 4956751.2 | C16: 7732071.2 | D16: 11648899 | E16: =Drivers!F55 -> 15918454 | F16: =Drivers!G55 -> 20333858 | G16: =Drivers!H55 -> 29808450 | H16: =Drivers!I55 -> 37525148 | I16: =Drivers!J55 -> 45985792
A17: Chi phí cố định | B17: 1055000 | C17: 1160500 | D17: 1276550 | E17: =Drivers!F56 -> 1404205 | F17: =Drivers!G56 -> 1544625.5 | G17: =Drivers!H56 -> 2599088 | H17: =Drivers!I56 -> 2858996.9 | I17: =Drivers!J56 -> 3144896.5
A18: Tiền lương bộ phận sản xuất (70% quỹ lương) | B18: =Drivers!$C$167*B55 -> 4894400 | C18: =Drivers!$C$167*C55 -> 5383840 | D18: =Drivers!$C$167*D55 -> 7537376 | E18: =Drivers!$C$167*E55 -> 10028626 | F18: =Drivers!$C$167*F55 -> 12838240 | G18: =Drivers!$C$167*G55 -> 18161074 | H18: =Drivers!$C$167*H55 -> 22798298 | I18: =Drivers!$C$167*I55 -> 26825045
A19: Khấu hao TSCĐ sản xuất (90% khấu hao) | B19: =Drivers!$C$168*B71 -> 1288980 | C19: =Drivers!$C$168*C71 -> 2137752 | D19: =Drivers!$C$168*D71 -> 2818756.8 | E19: =Drivers!$C$168*E71 -> 3367885 | F19: =Drivers!$C$168*F71 -> 4743239.4 | G19: =Drivers!$C$168*G71 -> 10341031 | H19: =Drivers!$C$168*H71 -> 11771837 | I19: =Drivers!$C$168*I71 -> 13301163
A20: Tổng Giá vốn hàng bán | B20: =SUM(B16:B19) -> 12195131 | C20: =SUM(C16:C19) -> 16414163 | D20: =SUM(D16:D19) -> 23281582 | E20: =SUM(E16:E19) -> 30719170 | F20: =SUM(F16:F19) -> 39459963 | G20: =SUM(G16:G19) -> 60909642 | H20: =SUM(H16:H19) -> 74954279 | I20: =SUM(I16:I19) -> 89256897
A21: Lợi nhuận gộp | B21: =B13-B20 -> 7243108.8 | C21: =C13-C20 -> 14514122 | D21: =D13-D20 -> 24264946 | E21: =E13-E20 -> 32954647 | F21: =F13-F20 -> 40280657 | G21: =G13-G20 -> 49492023 | H21: =H13-H20 -> 66650054 | I21: =I13-I20 -> 81060851
A22: Biên lợi nhuận gộp | B22: =B21/B13 -> 0.37262164 | C22: =C21/C13 -> 0.46928311 | D22: =D21/D13 -> 0.51034107 | E22: =E21/E13 -> 0.51755412 | F22: =F21/F13 -> 0.50514602 | G22: =G21/G13 -> 0.44829054 | H22: =H21/H13 -> 0.47067807 | I22: =I21/I13 -> 0.47593895
A23: Chi phí
A24: Chi phí Bán hàng và quản lý doanh nghiệp
A25: Tiền lương bộ phận bán hàng & quản lý (30% quỹ lương) | B25: =(1-Drivers!$C$167)*B55 -> 2097600 | C25: =(1-Drivers!$C$167)*C55 -> 2307360 | D25: =(1-Drivers!$C$167)*D55 -> 3230304 | E25: =(1-Drivers!$C$167)*E55 -> 4297982.6 | F25: =(1-Drivers!$C$167)*F55 -> 5502102.8 | G25: =(1-Drivers!$C$167)*G55 -> 7783317.4 | H25: =(1-Drivers!$C$167)*H55 -> 9770698.9 | I25: =(1-Drivers!$C$167)*I55 -> 11496448
A26: Thuê mặt bằng | B26: 3977000 | C26: 5368950 | D26: 7570219.5 | E26: =Drivers!F66 -> 8478645.8 | F26: =Drivers!G66 -> 9750442.7 | G26: =Drivers!H66 -> 12675576 | H26: =Drivers!I66 -> 14196645 | I26: =Drivers!J66 -> 15900242
A27: Khấu hao TSCĐ bộ phận bán hàng & quản lý (10% khấu hao) | B27: =(1-Drivers!$C$168)*B71 -> 143220 | C27: =(1-Drivers!$C$168)*C71 -> 237528 | D27: =(1-Drivers!$C$168)*D71 -> 313195.2 | E27: =(1-Drivers!$C$168)*E71 -> 374209.44 | F27: =(1-Drivers!$C$168)*F71 -> 527026.6 | G27: =(1-Drivers!$C$168)*G71 -> 1149003.4 | H27: =(1-Drivers!$C$168)*H71 -> 1307981.8 | I27: =(1-Drivers!$C$168)*I71 -> 1477907
A28: Sửa chữa, bảo dưỡng | B28: 950000 | C28: 1615000 | D28: 2083350 | E28: =Drivers!F68 -> 2801647.9 | F28: =Drivers!G68 -> 3508587.3 | G28: =Drivers!H68 -> 4857673.3 | H28: =Drivers!I68 -> 6230590.6 | I28: =Drivers!J68 -> 7493980.9
A29: Furniture & Fixtures | B29: 0 | C29: 0 | D29: 0 | E29: 0 | F29: 0 | G29: 0 | H29: 0 | I29: 0
A30: Chi phí dịch vụ chung (điện, nước...) | B30: 1200000 | C30: 1800000 | D30: 2250000 | E30: =Drivers!F70 -> 3183690.8 | F30: =Drivers!G70 -> 3987031 | G30: =Drivers!H70 -> 5520083.2 | H30: =Drivers!I70 -> 7080216.6 | I30: =Drivers!J70 -> 8515887.4
A31: Internet & Communications | B31: 0 | C31: 0 | D31: 0 | E31: 0 | F31: 0 | G31: 0 | H31: 0 | I31: 0
A32: Infrastructure Services | B32: 0 | C32: 0 | D32: 0 | E32: 0 | F32: 0 | G32: 0 | H32: 0 | I32: 0
A33: Software | B33: 0 | C33: 0 | D33: 0 | E33: 0 | F33: 0 | G33: 0 | H33: 0 | I33: 0
A34: Bank Service Charges | B34: 0 | C34: 0 | D34: 0 | E34: 0 | F34: 0 | G34: 0 | H34: 0 | I34: 0
A35: Business Licenses and Permits | B35: 0 | C35: 0 | D35: 0 | E35: 0 | F35: 0 | G35: 0 | H35: 0 | I35: 0
A36: Conferences, Dues, and Subscriptions | B36: 0 | C36: 0 | D36: 0 | E36: 0 | F36: 0 | G36: 0 | H36: 0 | I36: 0
A37: Văn phòng phẩm | B37: 0 | C37: 0 | D37: 0 | E37: 0 | F37: 0 | G37: 0 | H37: 0 | I37: 0
A38: Gifts | B38: 0 | C38: 0 | D38: 0 | E38: 0 | F38: 0 | G38: 0 | H38: 0 | I38: 0
A39: Printing , Postage and Delivery | B39: 0 | C39: 0 | D39: 0 | E39: 0 | F39: 0 | G39: 0 | H39: 0 | I39: 0
A40: Miscellaneous | B40: 0 | C40: 0 | D40: 0 | E40: 0 | F40: 0 | G40: 0 | H40: 0 | I40: 0
A41: Recruiting Expense | B41: 0 | C41: 0 | D41: 0 | E41: 0 | F41: 0 | G41: 0 | H41: 0 | I41: 0
A42: Hỗ trợ tiền ăn cho CNV | B42: 2150000 | C42: 2580000 | D42: 3096000 | E42: =Drivers!F64 -> 4011450.5 | F42: =Drivers!G64 -> 5135295.9 | G42: =Drivers!H64 -> 7264429.6 | H42: =Drivers!I64 -> 9119319 | I42: =Drivers!J64 -> 10730018
A43: Equipment Rental | B43: 0 | C43: 0 | D43: 0 | E43: 0 | F43: 0 | G43: 0 | H43: 0 | I43: 0
A44: Other Tech Expense | B44: 0 | C44: 0 | D44: 0 | E44: 0 | F44: 0 | G44: 0 | H44: 0 | I44: 0
...

Sheet Balance Sheet
B1: Balance Sheet
G2: Đơn vị: Nghìn đồng
D3: ='Hướng dẫn'!J6-3 -> 2023 | F3: =D3+1 -> 2024 | G3: =F3+1 -> 2025 | H3: =G3+1 -> 2026 | I3: =H3+1 -> 2027 | J3: =I3+1 -> 2028 | K3: =J3+1 -> 2029 | L3: =K3+1 -> 2030 | M3: Ngoài kỳ dự phóng – không sử dụng
A4: Tài sản ngắn hạn | D4: 01/01/2023 (đầu kỳ) | E4: 31/12/2023
B5: Tiền và các khoản tương đương tiền
C6: Tiền mặt | D6: 910000 | E6: 43988.8 | F6: 1735532.6 | G6: 2933481.8 | H6: ='Cash Flow Statement'!F36 -> 35546329 | I6: ='Cash Flow Statement'!G36 -> 22631264 | J6: ='Cash Flow Statement'!H36 -> 16331816 | K6: ='Cash Flow Statement'!I36 -> 11367772 | L6: ='Cash Flow Statement'!J36 -> 11935048
C7: Tổng tiền mặt | D7: 910000 | E7: 43988.8 | F7: 1735532.6 | G7: 2933481.8 | H7: =SUBTOTAL(9,H6) -> 35546329 | I7: =SUBTOTAL(9,I6) -> 22631264 | J7: =SUBTOTAL(9,J6) -> 16331816 | K7: =SUBTOTAL(9,K6) -> 11367772 | L7: =SUBTOTAL(9,L6) -> 11935048
B8: Hàng tồn kho
C9: Hàng tồn kho | D9: 1785000 | E9: 2499000 | F9: 2998800 | G9: 3748500 | H9: =Drivers!F105 -> 4745934 | I9: =Drivers!G105 -> 5994105.1 | J9: =Drivers!H105 -> 9322716.3 | K9: =Drivers!I105 -> 11064149 | L9: =Drivers!J105 -> 12787439
C10: Tổng hàng tồn kho | D10: 1785000 | E10: 2499000 | F10: 2998800 | G10: 3748500 | H10: =SUBTOTAL(9, H9) -> 4745934 | I10: =SUBTOTAL(9, I9) -> 5994105.1 | J10: =SUBTOTAL(9, J9) -> 9322716.3 | K10: =SUBTOTAL(9, K9) -> 11064149 | L10: =SUBTOTAL(9, L9) -> 12787439
B11: Khoản phải thu
C12: Phải thu khách hàng | D12: 1050000 | E12: 1260000 | F12: 1537200 | G12: 1767780 | H12: =Drivers!F107 -> 3140078.6 | I12: =Drivers!G107 -> 4806284 | J12: =Drivers!H107 -> 7864228.2 | K12: =Drivers!I107 -> 11638712 | L12: =Drivers!J107 -> 13998719
C13: Tổng khoản phải thu | D13: 1050000 | E13: 1260000 | F13: 1537200 | G13: 1767780 | H13: =SUBTOTAL(9, H12) -> 3140078.6 | I13: =SUBTOTAL(9, I12) -> 4806284 | J13: =SUBTOTAL(9, J12) -> 7864228.2 | K13: =SUBTOTAL(9, K12) -> 11638712 | L13: =SUBTOTAL(9, L12) -> 13998719
B14: Tài sản ngắn hạn khác
C15: Other Receivable | D15: 0 | E15: 0 | F15: 0 | G15: 0 | H15: 0 | I15: 0 | J15: 0 | K15: 0 | L15: 0
C16: Chi phí trả trước | D16: 890000 | E16: 1068000 | F16: 1495200 | G16: 1794240 | H16: =Drivers!F109*$G$16/$G$20 -> 2204363.7 | I16: =Drivers!G109*$G$16/$G$20 -> 2760590.4 | J16: =Drivers!H109*$G$16/$G$20 -> 3822064.3 | K16: =Drivers!I109*$G$16/$G$20 -> 4902289 | L16: =Drivers!J109*$G$16/$G$20 -> 5896336.7
C17: Prepaid Insurance | D17: - | E17: - | F17: - | G17: - | H17: 0 | I17: 0 | J17: 0 | K17: 0 | L17: 0
C18: Unbilled Revenue | D18: - | E18: - | F18: - | G18: - | H18: 0 | I18: 0 | J18: 0 | K18: 0 | L18: 0
C19: Tài sản ngắn hạn khác | D19: 150000 | E19: 165000 | F19: 214500 | G19: 278850 | H19: =Drivers!F109*$G$19/$G$20 -> 342588.96 | I19: =Drivers!G109*$G$19/$G$20 -> 429034.38 | J19: =Drivers!H109*$G$19/$G$20 -> 594002.27 | K19: =Drivers!I109*$G$19/$G$20 -> 761884.3 | L19: =Drivers!J109*$G$19/$G$20 -> 916373.22
C20: Tổng tài sản ngắn hạn khác | D20: 1040000 | E20: 1233000 | F20: 1709700 | G20: 2073090 | H20: =SUBTOTAL(9,H15:H19) -> 2546952.7 | I20: =SUBTOTAL(9,I15:I19) -> 3189624.8 | J20: =SUBTOTAL(9,J15:J19) -> 4416066.6 | K20: =SUBTOTAL(9,K15:K19) -> 5664173.3 | L20: =SUBTOTAL(9,L15:L19) -> 6812709.9
B22: Tổng tài sản ngắn hạn | D22: 4785000 | E22: 5035988.8 | F22: 7981232.5 | G22: 10522852 | H22: =SUBTOTAL(9,H5:H21) -> 45979295 | I22: =SUBTOTAL(9,I5:I21) -> 36621278 | J22: =SUBTOTAL(9,J5:J21) -> 37934827 | K22: =SUBTOTAL(9,K5:K21) -> 39734807 | L22: =SUBTOTAL(9,L5:L21) -> 45533916
D23: 0 | E23: 0 | F23: 0 | G23: 0
A24: Tài sản dài hạn
B25: Khấu khao
C26: Khấu hao lũy kế | D26: 2850000 | E26: 4282200 | F26: 6657480 | G26: 9789432 | H26: =G26+'Income Statement'!E71 -> 13531526 | I26: =H26+'Income Statement'!F71 -> 18801792 | J26: =I26+'Income Statement'!G71 -> 30291827 | K26: =J26+'Income Statement'!H71 -> 43371645 | L26: =K26+'Income Statement'!I71 -> 58150715
C27: Accumulated Amortization | D27: 0 | E27: 0 | F27: 0 | G27: 0 | H27: =G27+'Income Statement'!E72 -> 0 | I27: =H27+'Income Statement'!F72 -> 0 | J27: =I27+'Income Statement'!G72 -> 0 | K27: =J27+'Income Statement'!H72 -> 0 | L27: =K27+'Income Statement'!I72 -> 0
B28: Tài sản dài hạn
C29: Tài sản cố định vô hình | D29: 985000 | E29: 985000 | F29: 1020000 | G29: 1020000 | H29: =G29 -> 1020000 | I29: =H29 -> 1020000 | J29: =I29 -> 1020000 | K29: =J29 -> 1020000 | L29: =K29 -> 1020000
C30: Thiết bị, nhà xưởng | D30: 10220000 | E30: 13797000 | F30: 19315800 | G30: 21633696 | H30: =G30+Drivers!F95 -> 34368459 | I30: =H30+Drivers!G95 -> 86199862 | J30: =I30+Drivers!H95 -> 99448062 | K30: =J30+Drivers!I95 -> 1.136085e+08 | L30: =K30+Drivers!J95 -> 1.3064027e+08
C31: Văn phòng | D31: 3580000 | E31: 5012000 | F31: 5763800 | G31: 8530424 | H31: =G31 -> 8530424 | I31: =H31 -> 8530424 | J31: =I31 -> 8530424 | K31: =J31 -> 8530424 | L31: =K31 -> 8530424
B32: Tổng tài sản dài hạn | D32: 11935000 | E32: 15511800 | F32: 19442120 | G32: 21394688 | H32: =SUM(H29:H31)-H26-H27 -> 30387357 | I32: =SUM(I29:I31)-I26-I27 -> 76948494 | J32: =SUM(J29:J31)-J26-J27 -> 78706659 | K32: =SUM(K29:K31)-K26-K27 -> 79787274 | L32: =SUM(L29:L31)-L26-L27 -> 82039979
A34: Tổng tài sản | D34: 16720000 | E34: 20547789 | F34: 27423353 | G34: 31917540 | H34: =H22+H32 -> 76366652 | I34: =I22+I32 -> 1.1356977e+08 | J34: =J22+J32 -> 1.1664149e+08 | K34: =K22+K32 -> 1.1952208e+08 | L34: =L22+L32 -> 1.2757389e+08
D35: 0 | E35: 0 | F35: 0 | G35: 0
A37: Nợ phải trả và Vốn chủ sở hữu
A38: Nợ ngắn hạn
B39: Khoản phải trả
C40: Phải trả người bán | D40: 120000 | E40: 156000 | F40: 202800 | G40: 263640 | H40: =Drivers!F111 -> 474593.4 | I40: =Drivers!G111 -> 719292.61 | J40: =Drivers!H111 -> 1331816.6 | K40: =Drivers!I111 -> 1659622.4 | L40: =Drivers!J111 -> 2019069.4
C41: Tổng khoản khải trả | D41: 120000 | E41: 156000 | F41: 202800 | G41: 263640 | H41: =SUBTOTAL(9, H40) -> 474593.4 | I41: =SUBTOTAL(9, I40) -> 719292.61 | J41: =SUBTOTAL(9, J40) -> 1331816.6 | K41: =SUBTOTAL(9, K40) -> 1659622.4 | L41: =SUBTOTAL(9, L40) -> 2019069.4
B42: Credit Cards
C43: Credit Card 1 | D43: 0 | E43: 0 | F43: 0 | G43: 0 | H43: 0 | I43: 0 | J43: 0 | K43: 0 | L43: 0
...

Sheet Cash Flow Statement
A1: Statement of Cash Flows
E3: Đơn vị: Nghìn đồng
C4: ='Income Statement'!B4 -> 2023 | D4: =C4+1 -> 2024 | E4: =D4+1 -> 2025 | F4: =E4+1 -> 2026 | G4: =F4+1 -> 2027 | H4: =G4+1 -> 2028 | I4: =H4+1 -> 2029 | J4: =I4+1 -> 2030 | K4: Ngoài kỳ dự phóng – không sử dụng
A5: Hoạt động kinh doanh
B6: Lợi nhuận sau thuế | C6: -4309011.2 | D6: -503276.25 | E6: 4420495.2 | F6: ='Income Statement'!E80 -> 6579139.9 | G6: ='Income Statement'!F80 -> 5827445.2 | H6: ='Income Statement'!G80 -> 2397868.8 | I6: ='Income Statement'!H80 -> 8710152.1 | J6: ='Income Statement'!I80 -> 13854708
B8: Khấu hao | C8: 1432200 | D8: 2375280 | E8: 3131952 | F8: ='Income Statement'!E71 -> 3742094.4 | G8: ='Income Statement'!F71 -> 5270266 | H8: ='Income Statement'!G71 -> 11490034 | I8: ='Income Statement'!H71 -> 13079818 | J8: ='Income Statement'!I71 -> 14779070
A10: Biến động Tài sản ngắn hạn
B11: Khoản phải thu | C11: -210000 | D11: -277200 | E11: -230580 | F11: ='Balance Sheet'!G12-'Balance Sheet'!H12 -> -1372298.6 | G11: ='Balance Sheet'!H12-'Balance Sheet'!I12 -> -1666205.3 | H11: ='Balance Sheet'!I12-'Balance Sheet'!J12 -> -3057944.2 | I11: ='Balance Sheet'!J12-'Balance Sheet'!K12 -> -3774484.1 | J11: ='Balance Sheet'!K12-'Balance Sheet'!L12 -> -2360006.7
B12: Hàng tồn kho | C12: -714000 | D12: -499800 | E12: -749700 | F12: ='Balance Sheet'!G10-'Balance Sheet'!H10 -> -997434.04 | G12: ='Balance Sheet'!H10-'Balance Sheet'!I10 -> -1248171.1 | H12: ='Balance Sheet'!I10-'Balance Sheet'!J10 -> -3328611.2 | I12: ='Balance Sheet'!J10-'Balance Sheet'!K10 -> -1741433 | J12: ='Balance Sheet'!K10-'Balance Sheet'!L10 -> -1723290.2
B13: Tài sản ngắn hạn khác | C13: -193000 | D13: -476700 | E13: -363390 | F13: ='Balance Sheet'!G20-'Balance Sheet'!H20 -> -473862.68 | G13: ='Balance Sheet'!H20-'Balance Sheet'!I20 -> -642672.12 | H13: ='Balance Sheet'!I20-'Balance Sheet'!J20 -> -1226441.8 | I13: ='Balance Sheet'!J20-'Balance Sheet'!K20 -> -1248106.7 | J13: ='Balance Sheet'!K20-'Balance Sheet'!L20 -> -1148536.6
A14: Biến động Nợ ngắn hạn
B15: Khoản phải trả | C15: 36000 | D15: 46800 | E15: 60840 | F15: ='Balance Sheet'!H41-'Balance Sheet'!G41 -> 210953.4 | G15: ='Balance Sheet'!I41-'Balance Sheet'!H41 -> 244699.21 | H15: ='Balance Sheet'!J41-'Balance Sheet'!I41 -> 612524 | I15: ='Balance Sheet'!K41-'Balance Sheet'!J41 -> 327805.78 | J15: ='Balance Sheet'!L41-'Balance Sheet'!K41 -> 359446.99
B16: ='Balance Sheet'!B46 -> Nợ vay ngắn hạn | C16: -10000 | D16: 18000 | E16: -5400 | F16: ='Balance Sheet'!H48-'Balance Sheet'!G48 -> 0 | G16: ='Balance Sheet'!I48-'Balance Sheet'!H48 -> 0 | H16: ='Balance Sheet'!J48-'Balance Sheet'!I48 -> 0 | I16: ='Balance Sheet'!K48-'Balance Sheet'!J48 -> 0 | J16: ='Balance Sheet'!L48-'Balance Sheet'!K48 -> 0
B17: Nợ ngắn hạn khác | C17: 10800 | D17: 14040 | E17: 18252 | F17: =('Balance Sheet'!H56-'Balance Sheet'!G56)+('Balance Sheet'!H51-'Balance Sheet'!G51) -> 48255.634 | G17: =('Balance Sheet'!I56-'Balance Sheet'!H56)+('Balance Sheet'!I51-'Balance Sheet'!H51) -> 32133.606 | H17: =('Balance Sheet'!J56-'Balance Sheet'!I56)+('Balance Sheet'!J51-'Balance Sheet'!I51) -> 61322.09 | I17: =('Balance Sheet'!K56-'Balance Sheet'!J56)+('Balance Sheet'!K51-'Balance Sheet'!J51) -> 62405.335 | J17: =('Balance Sheet'!L56-'Balance Sheet'!K56)+('Balance Sheet'!L51-'Balance Sheet'!K51) -> 57426.831
A19: Lưu chuyển tiền thuần từ hoạt động kinh doanh | C19: -3957011.2 | D19: 697143.75 | E19: 6282469.2 | F19: =SUM(F6:F18) -> 7736847.9 | G19: =SUM(G6:G18) -> 7817495.5 | H19: =SUM(H6:H18) -> 6948752.1 | I19: =SUM(I6:I18) -> 15416158 | J19: =SUM(J6:J18) -> 23818819
A21: Đầu tư
B22: Biến động Tài sản cố định | C22: -5009000 | D22: -6305600 | E22: -5084520 | F22: =SUM('Balance Sheet'!G29:G31)-SUM('Balance Sheet'!H29:H31) -> -12734763 | G22: =SUM('Balance Sheet'!H29:H31)-SUM('Balance Sheet'!I29:I31) -> -51831403 | H22: =SUM('Balance Sheet'!I29:I31)-SUM('Balance Sheet'!J29:J31) -> -13248200 | I22: =SUM('Balance Sheet'!J29:J31)-SUM('Balance Sheet'!K29:K31) -> -14160433 | J22: =SUM('Balance Sheet'!K29:K31)-SUM('Balance Sheet'!L29:L31) -> -17031775
A24: Lưu chuyển tiền thuần từ hoạt động đầu tư | C24: -5009000 | D24: -6305600 | E24: -5084520 | F24: =SUM(F22:F23) -> -12734763 | G24: =SUM(G22:G23) -> -51831403 | H24: =SUM(H22:H23) -> -13248200 | I24: =SUM(I22:I23) -> -14160433 | J24: =SUM(J22:J23) -> -17031775
A26: Tài chính
B27: Nhận vốn góp cổ phần | C27: 8100000 | D27: 7000000 | E27: 0 | F27: ='Balance Sheet'!H72 -> 37610763 | G27: ='Balance Sheet'!I72 -> 0 | H27: ='Balance Sheet'!J72 -> 0 | I27: ='Balance Sheet'!K72 -> 0 | J27: ='Balance Sheet'!L72 -> 0
B28: Vay (trả) nợ dài hạn | C28: 0 | D28: 300000 | E28: 0 | F28: =('Balance Sheet'!H61-'Balance Sheet'!G61) -> 0 | G28: =('Balance Sheet'!I61-'Balance Sheet'!H61) -> 31098842 | H28: =('Balance Sheet'!J61-'Balance Sheet'!I61) -> 0 | I28: =('Balance Sheet'!K61-'Balance Sheet'!J61) -> -6219768.4 | J28: =('Balance Sheet'!L61-'Balance Sheet'!K61) -> -6219768.4
A30: Lưu chuyển tiền thuần từ hoạt động tài chính | C30: 8100000 | D30: 7300000 | E30: 0 | F30: =SUM(F27:F29) -> 37610763 | G30: =SUM(G27:G29) -> 31098842 | H30: =SUM(H27:H29) -> 0 | I30: =SUM(I27:I29) -> -6219768.4 | J30: =SUM(J27:J29) -> -6219768.4
A32: Số dư tiền mặt đầu kỳ | C32: 910000 | D32: 43988.8 | E32: 1735532.6 | F32: =E36 -> 2933481.8 | G32: =F36 -> 35546329 | H32: =G36 -> 22631264 | I32: =H36 -> 16331816 | J32: =I36 -> 11367772
A34: Biến động tiền mặt trong kỳ | C34: -866011.2 | D34: 1691543.8 | E34: 1197949.2 | F34: =F19+F24+F30 -> 32612848 | G34: =G19+G24+G30 -> -12915066 | H34: =H19+H24+H30 -> -6299447.7 | I34: =I19+I24+I30 -> -4964043.9 | J34: =J19+J24+J30 -> 567275.57
A36: Số dư tiền mặt cuối kỳ | C36: 43988.8 | D36: 1735532.6 | E36: 2933481.8 | F36: =F34+F32 -> 35546329 | G36: =G34+G32 -> 22631264 | H36: =H34+H32 -> 16331816 | I36: =I34+I32 -> 11367772 | J36: =J34+J32 -> 11935048

Sheet Discount rate
A1: Discount rate calculation
A3: Beta | B3: =B23 -> 1.4787208 | C3: Beta tổng của AgriPack (B23 = beta có đòn bẩy / ρ); chỉ dùng trong chi phí vốn chủ sở hữu ở E3. | D3: Chi phí vốn CSH | E3: =B4+B3*(B5-B4) -> 0.159427 | F3: CAPM: Ke = Rf + β × (Rm − Rf)
A4: Risk-free rate | B4: =B13 -> 0.039207 | D4: Chi phí vốn nợ (sau thuế) | E4: =B15*(1-Assumption!D15) -> 0.08 | F4: Kd × (1 − thuế suất)
A5: Market return | B5: =B24 -> 0.120507 | C5: Rm = Rf + ERP Việt Nam (B24). Thị trường có beta bằng 1 nên lợi suất thị trường không nhân beta. | D5: WACC | E5: =(B7*E3+B8*E4)/B9 -> 0.13637833 | F5: WACC = E/(D + E) × Ke + D/(D + E) × Kd × (1 − t)
A7: Vốn CSH | B7: ='Balance Sheet'!I76 -> 79989556
A8: Nợ vay dài hạn | B8: ='Balance Sheet'!I61+'Balance Sheet'!I48 -> 32701442
A9: Total | B9: =B7+B8 -> 1.12691e+08
A12: CƠ SỞ TÍNH CHI PHÍ VỐN | C12: Nguồn / lý do (ghi ngay cạnh ô giả định)
A13: Lợi suất phi rủi ro Rf = bình quân lợi suất TPCP 10 năm, 2016–2025 | B13: =B40 -> 0.039207 | C13: Lý do: bình quân lợi suất TPCP kỳ hạn 10 năm của 10 năm 2016–2025 (bảng A28:D40) để không đưa đỉnh/đáy chu kỳ lãi suất vào chi phí vốn dài hạn
A14: ERP thị trường phát triển | B14: 0.0423 | C14: Nguồn: Damodaran (01/2026) – ERP thị trường trưởng thành (Aaa) 4,23%; bản 07/2026: 4,20%.
A15: Lãi suất vay trước thuế (Kd) | B15: 0.1 | C15: Lý do: lãi suất cho vay VND 8,1–10,5%/năm (6/2026); DN nhỏ vay ở nửa trên khung → 10%. Nguồn: NHNN (2026), Mục 3.1.3.
A16: Phần bù rủi ro quốc gia Việt Nam (CRP) | B16: 0.039 | C16: ƯỚC TÍNH: Moody's Ba2 (triển vọng tích cực từ 5/2026); chênh lệch vỡ nợ Ba2 ~2,9% × hệ số biến động cổ phiếu/trái phiếu ~1,35 (phương pháp Damodaran). Nguồn: Moody's (2026); Damodaran (2026).
A17: ERP Việt Nam = ERP phát triển + CRP | B17: =B14+B16 -> 0.0813
A18: Beta không đòn bẩy ngành bao bì (βu) | B18: 0.78 | C18: Nguồn: Damodaran (01/2026) – beta không đòn bẩy ngành Packaging & Container 0,78 (hiệu chỉnh tiền mặt 0,81). Beta 2 năm của DN bao bì niêm yết VN thấp (~0,6) do thanh khoản mỏng nên không dùng.
A19: D/E mục tiêu (BCĐKT dự phóng 2027, sau huy động) | B19: =B8/B7 -> 0.40882139 | C19: Công thức: D/E theo BCĐKT dự phóng cuối 2027 (sau huy động vốn cổ phần và khoản vay trung hạn).
A20: Thuế suất | B20: =Assumption!D15 -> 0.2 | C20: Nguồn: Luật Thuế TNDN 67/2025/QH15 (20%).
A21: Beta có đòn bẩy = βu × [1 + (1 − t) × D/E] | B21: =B18*(1+(1-B20)*B19) -> 1.0351046
A22: Hệ số tương quan ρ (NĐT VC đa dạng hóa một phần) | B22: 0.7 | C22: Công thức: beta tổng = beta có đòn bẩy / ρ (B23 = B21/B22), trong đó ρ là hệ số tương quan giữa danh mục của nhà đầu tư VC và thị trường. ρ = 0,7 vì quỹ VC nắm 20–30 khoản đầu tư nên chỉ đa dạng hóa một phần. Nguồn: Damodaran (2009), Valuing Young, Start-up and Growth Companies.
A23: Beta điều chỉnh cho startup (total beta = β / ρ) | B23: =B21/B22 -> 1.4787208
A24: Lợi suất thị trường kỳ vọng = Rf + ERP Việt Nam | B24: =B13+B17 -> 0.120507
A26: Ghi chú: Trọng số theo cơ cấu vốn mục tiêu (BCĐKT dự phóng cuối 2027, sau Series A và khoản vay trung hạn). CAPM với total beta phản ánh rủi ro phi hệ thống mà NĐT VC không đa dạng hóa hết; rủi ro thất bại được xử lý riêng ở VCM để tránh tính trùng.
A28: LỢI SUẤT TPCP KỲ HẠN 10 NĂM – BÌNH QUÂN 10 NĂM (cơ sở của Rf)
A29: Năm | B29: Lợi suất 10 năm | C29: Thời điểm quan sát | D29: Nguồn
A30: 2016 | B30: 0.0695 | C30: Q1/2016 – lãi suất phát hành kỳ hạn 10 năm | D30: Oxford Business Group (2017). The Report: Vietnam 2017 – Attractive yields (bonds)
A31: 2017 | B31: 0.0542 | C31: 10/2017 – lãi suất trúng thầu kỳ hạn 10 năm | D31: Vietnam News (2017), tin đấu thầu TPCP tháng 10/2017; tháng 11/2017: 5,41–5,91%
A32: 2018 | B32: 0.04997 | C32: 03/12/2018 – lợi suất spot kỳ hạn 10 năm | D32: CEIC Data (dữ liệu HNX), Vietnam Government Bond Yield: Spot
A33: 2019 | B33: 0.0342 | C33: 12/2019 – thị trường thứ cấp (mức thấp kỷ lục) | D33: Vietnam News (2020). Gov't bond yields hit record low
A34: 2020 | B34: 0.0224 | C34: 12/2020 – thị trường thứ cấp (−34 bps so với 11/2020) | D34: VBMA (2021). Bond Market Report 12/2020; MBS Fixed Income 01/2021
A35: 2021 | B35: 0.0209 | C35: 12/2021 – thị trường thứ cấp | D35: VBMA (2022). Bond Market Monthly Highlights 12/2021
A36: 2022 | B36: 0.048 | C36: 31/12/2022 – thị trường thứ cấp | D36: ADB AsianBondsOnline (2023); VBMA Monthly Bond Market Report 12/2022
A37: 2023 | B37: 0.0228 | C37: 29/11/2023 – lãi suất trúng thầu kỳ hạn 10 năm | D37: VBMA (2023). Kết quả đấu thầu TPCP ngày 29/11/2023
A38: 2024 | B38: 0.0297 | C38: Cuối năm 2024 – lợi suất kỳ hạn 10 năm | D38: Thị trường Tài chính Tiền tệ (2025). Thị trường TPCP: kỳ hạn 10 năm tiếp tục chi phối nhu cầu
A39: 2025 | B39: 0.0404 | C39: Cuối năm 2025 – lợi suất kỳ hạn 10 năm | D39: VNDirect (2025). La bàn thị trường; Thị trường Tài chính Tiền tệ (2026)
A40: Bình quân 2016–2025 = Rf dùng trong CAPM | B40: =AVERAGE(B30:B39) -> 0.039207
A41: Tham khảo: lợi suất hiện hành đầu 06/2026 ~4,47%; 03/04/2026 4,35% (TradingEconomics). Dùng bình quân 10 năm để không đưa đỉnh/đáy chu kỳ lãi suất vào chi phí vốn dài hạn; 2016–2017 dùng quan sát phát hành/đấu thầu gần nhất có nguồn.

Sheet Assumption
A1: Assumption
D2: 0 | E2: 1 | F2: 2 | G2: 3 | H2: 4 | I2: 5
D3: ='Income Statement'!D4 -> 2025 | E3: =D3+1 -> 2026 | F3: =E3+1 -> 2027 | G3: =F3+1 -> 2028 | H3: =G3+1 -> 2029 | I3: =H3+1 -> 2030
A4: % Tăng trưởng doanh thu | D4: ='Income Statement'!D13/'Income Statement'!C13-1 -> 0.53731538 | E4: =Drivers!F40 -> 0.33918962 | F4: =Drivers!G40 -> 0.25232982 | G4: =Drivers!H40 -> 0.38450974 | H4: =Drivers!I40 -> 0.2826286 | I4: =Drivers!J40 -> 0.20277215
A5: GVHB/Doanh thu | D5: ='Income Statement'!D20/'Income Statement'!D13 -> 0.48965893 | E5: =Drivers!F83 -> 0.48244588 | F5: =Drivers!G83 -> 0.49485398 | G5: =Drivers!H83 -> 0.55170946 | H5: =Drivers!I83 -> 0.52932193 | I5: =Drivers!J83 -> 0.52406105
A6: Tổng CP hoạt động/Doanh thu | D6: ='Income Statement'!D63/'Income Statement'!D13 -> 0.4143787 | E6: =Drivers!F89 -> 0.39753447 | F6: =Drivers!G89 -> 0.39228625 | G6: =Drivers!H89 -> 0.39152075 | H6: =Drivers!I89 -> 0.3728926 | I6: =Drivers!J89 -> 0.36053369
A7: CP Tài chính/Doanh thu | D7: ='Income Statement'!D69/'Income Statement'!D13 -> 0.0029903761 | E7: =Drivers!F130 -> 0.0025168901 | F7: =Drivers!G130 -> 0.021509766 | G7: =Drivers!H130 -> 0.029620425 | H7: =Drivers!I130 -> 0.020897353 | I7: =Drivers!J130 -> 0.013722463
A8: TSNH (ngoài tiền)/Doanh thu | D8: =('Balance Sheet'!G22-'Balance Sheet'!G7)/'Income Statement'!D13 -> 0.15961986 | E8: =(Drivers!F105+Drivers!F107+Drivers!F109)/Drivers!F39 -> 0.16385016 | F8: =(Drivers!G105+Drivers!G107+Drivers!G109)/Drivers!G39 -> 0.17544401 | G8: =(Drivers!H105+Drivers!H107+Drivers!H109)/Drivers!H39 -> 0.1956765 | H8: =(Drivers!I105+Drivers!I107+Drivers!I109)/Drivers!I39 -> 0.20032604 | I8: =(Drivers!J105+Drivers!J107+Drivers!J109)/Drivers!J39 -> 0.19727168
A9: Nợ ngắn hạn (ngoài vay)/Doanh thu | D9: =('Balance Sheet'!G58-'Balance Sheet'!G48)/'Income Statement'!D13 -> 0.0072083497 | E9: =(Drivers!F111+Drivers!F113)/Drivers!F39 -> 0.0094535096 | F9: =(Drivers!G111+Drivers!G113)/Drivers!G39 -> 0.011020404 | G9: =(Drivers!H111+Drivers!H113)/Drivers!H39 -> 0.014063374 | H9: =(Drivers!I111+Drivers!I113)/Drivers!I39 -> 0.013720139 | I9: =(Drivers!J111+Drivers!J113)/Drivers!J39 -> 0.013854721
A10: Hàng tồn kho/TSNH ngoài tiền | D10: ='Balance Sheet'!G10/('Balance Sheet'!G22-'Balance Sheet'!G7) -> 0.49391451 | E10: =Drivers!F105/(Drivers!F105+Drivers!F107+Drivers!F109) -> 0.4548979 | F10: =Drivers!G105/(Drivers!G105+Drivers!G107+Drivers!G109) -> 0.42845598 | G10: =Drivers!H105/(Drivers!H105+Drivers!H107+Drivers!H109) -> 0.43154708 | H10: =Drivers!I105/(Drivers!I105+Drivers!I107+Drivers!I109) -> 0.39003545 | I10: =Drivers!J105/(Drivers!J105+Drivers!J107+Drivers!J109) -> 0.38059137
A11: Khoản phải thu/TSNH ngoài tiền | D11: ='Balance Sheet'!G13/('Balance Sheet'!G22-'Balance Sheet'!G7) -> 0.23292842 | E11: =Drivers!F107/(Drivers!F105+Drivers!F107+Drivers!F109) -> 0.30097662 | F11: =Drivers!G107/(Drivers!G105+Drivers!G107+Drivers!G109) -> 0.34355105 | G11: =Drivers!H107/(Drivers!H105+Drivers!H107+Drivers!H109) -> 0.36403389 | H11: =Drivers!I107/(Drivers!I105+Drivers!I107+Drivers!I109) -> 0.41029005 | I11: =Drivers!J107/(Drivers!J105+Drivers!J107+Drivers!J109) -> 0.41664257
A12: Khoản phải trả/Nợ NH ngoài vay | D12: ='Balance Sheet'!G41/('Balance Sheet'!G58-'Balance Sheet'!G48) -> 0.76923077 | E12: =Drivers!F111/(Drivers!F111+Drivers!F113) -> 0.78843836 | F12: =Drivers!G111/(Drivers!G111+Drivers!G113) -> 0.81851845 | G12: =Drivers!H111/(Drivers!H111+Drivers!H113) -> 0.85778662 | H12: =Drivers!I111/(Drivers!I111+Drivers!I113) -> 0.85422888 | I12: =Drivers!J111/(Drivers!J111+Drivers!J113) -> 0.85564487
A13: CAPEX/Doanh thu | D13: ='Pro Forma'!B25/'Income Statement'!D13 -> 0.10693778 | E13: =Drivers!F93 -> 0.2 | F13: =Drivers!G93 -> 0.65 | G13: =Drivers!H93 -> 0.12 | H13: =Drivers!I93 -> 0.1 | I13: =Drivers!J93 -> 0.1
A15: Thuế suất thuế TNDN | D15: 0.2 | E15: Nguồn: Luật Thuế TNDN 67/2025/QH15 – thuế suất phổ thông 20% (dùng cho NOPAT dài hạn và P/E chuẩn hóa).
A16: Tỷ lệ tăng trưởng vĩnh viễn | D16: 0.05 | E16: Lý do: tăng trưởng dài hạn danh nghĩa VND 5%: lạm phát mục tiêu ~4–4,5% cộng tăng trưởng thực thấp; thấp hơn GDP danh nghĩa VN (~10–12%) và thấp hơn Rf + tăng trưởng thực. Nguồn: NHNN, Quốc hội (mục tiêu CPI 2026 ~4,5%); Damodaran (2026).
A17: Tỷ lệ khấu hao | D17: 0.12 | E17: Nguồn: file Excel mẫu (12% nguyên giá đầu kỳ), khớp BCTC 2024–2025.
A18: Tỷ lệ chiết khấu WACC | D18: ='Discount rate'!E5 -> 0.13637833 | E18: Công thức: = WACC tính ở sheet Discount rate (E5).
A19: Lợi nhuận trên vốn đầu tư mới sau 2030 (RONIC) = ROIC 2030E | D19: =DCF!B39 -> 0.13881153 | E19: Công thức: RONIC = ROIC 2030E của chính mô hình (DCF!B39 = NOPAT 2030/(tài sản dài hạn ròng + VLĐ)). Lý do: file mẫu tính giá trị cuối kỳ = FCFF 2031/(WACC − g); FCFF 2031 được chuẩn hóa = NOPAT 2031 × (1 − g/RONIC) để phần tái đầu tư chỉ vừa đủ cho tăng trưởng 5%/năm, vì FCFF 2030 còn chứa CAPEX của giai đoạn tăng ~20%. Lấy RONIC bằng ROIC 2030 nghĩa là vốn mới sinh lời như năm cuối dự phóng, không giả định thêm lợi thế; ROIC 2030 xấp xỉ WACC nên tăng trưởng sau 2030 gần như không tạo thêm giá trị (thận trọng). Nguồn: tính toán từ mô hình; Damodaran (2026).
A21: Ghi chú: các tỷ lệ 2026E–2030E là kết quả của mô hình động lực ở sheet Drivers (sản lượng × giá, chi phí theo dòng, số ngày VLĐ, lịch CAPEX/vay/thuế) để tránh giả định % doanh thu thiếu cơ sở.

Sheet Drivers
A1: GIẢ ĐỊNH CHI TIẾT & MÔ HÌNH ĐỘNG LỰC (DRIVERS) – AgriPack
A2: Đơn vị: nghìn đồng (trừ khi ghi khác). Ô vàng chữ xanh dương = giả định/số liệu nhập; chữ đen = công thức; chữ xanh lá = liên kết sheet khác. Lịch sử 2023A–2025A liên kết từ BCTC do đề bài cung cấp.
A3: Kịch bản đang chạy (1 = Bear, 2 = Base, 3 = Bull) | C3: 2 | D3: =CHOOSE(C3,"Bear","Base","Bull") -> Base | K3: Ô chọn kịch bản: mọi hàng giả định kịch bản (mục F) được chọn bằng INDEX theo ô này.
A4: Năm thực hiện khoản đầu tư lớn (CAPEX/Doanh thu = 65%) | C4: 2027 | K4: Đề bài ghi 2027; template khóa 65% ở cột 2028 → base case theo đề bài, 2028 là độ nhạy (xem Summary).
A6: Chỉ tiêu | B6: Đơn vị / cơ sở | C6: 2023A | D6: 2024A | E6: 2025A | F6: 2026E | G6: 2027E | H6: 2028E | I6: 2029E | J6: 2030E | K6: Nguồn / lý do (ghi ngay cạnh ô giả định)
A7: năm (dùng cho công thức) | C7: 2023 | D7: 2024 | E7: 2025 | F7: 2026 | G7: 2027 | H7: 2028 | I7: 2029 | J7: 2030
A8: A. DOANH THU THEO PHÂN KHÚC (Sản lượng × Giá bán)
A9: A1. Bao bì F&B/FMCG (hộp, khay ép khuôn từ bã mía + vỏ trứng)
A10: Giá bán bình quân (ASP) | B10: nghìn đ/sản phẩm | E10: 2.5 | F10: =E10*(1+F11) -> 2.55 | G10: =F10*(1+G11) -> 2.601 | H10: =G10*(1+H11) -> 2.65302 | I10: =H10*(1+I11) -> 2.7060804 | J10: =I10*(1+J11) -> 2.760202 | K10: Lý do: giá 2025 lấy cận dưới khung giá hộp/khay 2.500–4.000đ/cái của nhóm vì doanh thu gồm cả khay nhỏ và đơn hàng sỉ; cao hơn hộp bã mía 500 ml bán lẻ 1.900–2.700đ nhờ ép khuôn theo mẫu. Nguồn: bảng chiến lược giá (Mục 1.2.2; ecoeshop.com), bảng giá hộp 500 ml (Mục 1.1.1; QueenPack.com, baobixanh.com).
A11: Tăng giá bán bình quân | B11: %/năm | F11: =INDEX($C$143:$E$143,$C$3) -> 0.02 | G11: =INDEX($C$143:$E$143,$C$3) -> 0.02 | H11: =INDEX($C$143:$E$143,$C$3) -> 0.02 | I11: =INDEX($C$143:$E$143,$C$3) -> 0.02 | J11: =INDEX($C$143:$E$143,$C$3) -> 0.02 | K11: Lý do: Base +2%/năm, thấp hơn CPI 8T/2026 (+4,45%) vì khách hàng B2B có sức mạnh đàm phán rất cao và bao bì nhựa rẻ hơn nhiều lần (Mục 3.1.2, 3.2.3); Bear +1%, Bull +2,5%. Nguồn: Cục Thống kê (2026); phân tích ngành của nhóm.
A12: Sản lượng quy đổi | B12: sản phẩm | C12: =C14/$E$10 -> 6022000 | D12: =D14/$E$10 -> 9635200 | E12: =E14/$E$10 -> 15223616 | F12: =E12*(1+F13) -> 20095173 | G12: =F12*(1+G13) -> 24516111 | H12: =G12*(1+H13) -> 33096750 | I12: =H12*(1+I13) -> 41370938 | J12: =I12*(1+J13) -> 48403997 | K12: Lịch sử = doanh thu / ASP 2025 (quy đổi, giả định giá không đổi 2023–25 – do BCTC không công bố sản lượng).
A13: Tăng trưởng sản lượng | B13: % | D13: =D12/C12-1 -> 0.6 | E13: =E12/D12-1 -> 0.58 | F13: =IF($C$4=2027,F149,F150)*INDEX($C$142:$E$142,$C$3) -> 0.32 | G13: =IF($C$4=2027,G149,G150)*INDEX($C$142:$E$142,$C$3) -> 0.22 | H13: =IF($C$4=2027,H149,H150)*INDEX($C$142:$E$142,$C$3) -> 0.35 | I13: =IF($C$4=2027,I149,I150)*INDEX($C$142:$E$142,$C$3) -> 0.25 | J13: =IF($C$4=2027,J149,J150)*INDEX($C$142:$E$142,$C$3) -> 0.17 | K13: Lý do: sản lượng bị giới hạn bởi công suất: 2026 +32% nhờ máy ép bổ sung (CAPEX 20% DT); 2027 +22% do nhà máy mới đang xây; 2028 +35% khi 2 nhà máy mới chạy; giảm dần về +17% năm 2030. Lịch sử +60% (2024), +58% (2025). Đối chiếu: thị phần SAM tăng từ 4,3% lên ~11% năm 2030. Nguồn: BCTC 2023–2025 (đề bài); IMARC Group (2025); giả định của nhóm.
A14: Doanh thu F&B/FMCG | B14: nghìn đồng | C14: ='Income Statement'!B6 -> 15055000 | D14: ='Income Statement'!C6 -> 24088000 | E14: ='Income Statement'!D6 -> 38059040 | F14: =F12*F10 -> 51242691 | G14: =G12*G10 -> 63766405 | H14: =H12*H10 -> 87806340 | I14: =I12*I10 -> 1.1195308e+08 | J14: =J12*J10 -> 1.3360481e+08
A16: A2. Thiết kế & sản xuất khuôn theo mẫu
A17: Giá bình quân/bộ khuôn | B17: nghìn đ/bộ | E17: 20000 | F17: =E17*(1+F18) -> 20400 | G17: =F17*(1+G18) -> 20808 | H17: =G17*(1+H18) -> 21224.16 | I17: =H17*(1+I18) -> 21648.643 | J17: =I17*(1+J18) -> 22081.616 | K17: Lý do: ~20 triệu đồng/bộ khuôn, bằng giá tham chiếu khuôn ép bã mía/tre. Nguồn: bảng chiến lược giá (Mục 1.2.2; HTAECO.com).
A18: Tăng giá | B18: %/năm | F18: =F11 -> 0.02 | G18: =G11 -> 0.02 | H18: =H11 -> 0.02 | I18: =I11 -> 0.02 | J18: =J11 -> 0.02
A19: Số bộ khuôn bàn giao | B19: bộ | C19: =C21/$E$17 -> 151 | D19: =D21/$E$17 -> 211.4 | E19: =E21/$E$17 -> 294.903 | F19: =E19*(1+F20) -> 359.78166 | G19: =F19*(1+G20) -> 424.54236 | H19: =G19*(1+H20) -> 543.41422 | I19: =H19*(1+I20) -> 652.09706 | J19: =I19*(1+J20) -> 749.91162
A20: Tăng trưởng số bộ khuôn | B20: % | D20: =D19/C19-1 -> 0.4 | E20: =E19/D19-1 -> 0.395 | F20: =F151*INDEX($C$142:$E$142,$C$3) -> 0.22 | G20: =G151*INDEX($C$142:$E$142,$C$3) -> 0.18 | H20: =H151*INDEX($C$142:$E$142,$C$3) -> 0.28 | I20: =I151*INDEX($C$142:$E$142,$C$3) -> 0.2 | J20: =J151*INDEX($C$142:$E$142,$C$3) -> 0.15 | K20: Lý do: số bộ khuôn gắn với số SKU/khách hàng mới; tăng nhanh năm 2028 khi mở thị trường miền Bắc, sau đó chậm dần. Lịch sử +40% (2024), +39,5% (2025). Nguồn: BCTC 2023–2025; giả định của nhóm.
A21: Doanh thu thiết kế & khuôn | B21: nghìn đồng | C21: ='Income Statement'!B7 -> 3020000 | D21: ='Income Statement'!C7 -> 4228000 | E21: ='Income Statement'!D7 -> 5898060 | F21: =F19*F17 -> 7339545.9 | G21: =G19*G17 -> 8833877.4 | H21: =H19*H17 -> 11533510 | I21: =I19*I17 -> 14117017 | J21: =J19*J17 -> 16559261
A23: A3. Đệm bảo vệ nội thất / thương mại điện tử
A24: Giá bình quân | B24: nghìn đ/m² | E24: 22.5 | F24: =E24*(1+F25) -> 22.8375 | G24: =F24*(1+G25) -> 23.180062 | H24: =G24*(1+H25) -> 23.527763 | I24: =H24*(1+I25) -> 23.88068 | J24: =I24*(1+J25) -> 24.23889 | K24: Lý do: trung điểm khung 15.000–30.000đ/m² của vật liệu đệm định hình (PE foam) mà sản phẩm thay thế. Nguồn: báo giá PE foam định hình trên thị trường (2026); Mục 3.2.6.
A25: Tăng giá | B25: %/năm | F25: =INDEX($C$144:$E$144,$C$3) -> 0.015 | G25: =INDEX($C$144:$E$144,$C$3) -> 0.015 | H25: =INDEX($C$144:$E$144,$C$3) -> 0.015 | I25: =INDEX($C$144:$E$144,$C$3) -> 0.015 | J25: =INDEX($C$144:$E$144,$C$3) -> 0.015 | K25: Lý do: đệm bảo vệ cạnh tranh trực tiếp với EPE/PE foam giá rẻ (áp lực thay thế cao, Mục 3.2.6) nên chỉ tăng 1,5%/năm (Base); Bear 0,5%, Bull 2%. Nguồn: phân tích ngành của nhóm.
A26: Diện tích quy đổi | B26: m² | C26: =C28/$E$24 -> 67555.556 | D26: =D28/$E$24 -> 101333.33 | E26: =E28/$E$24 -> 121600 | F26: =E26*(1+F27) -> 158080 | G26: =F26*(1+G27) -> 205504 | H26: =G26*(1+H27) -> 287705.6 | I26: =H26*(1+I27) -> 379771.39 | J26: =I26*(1+J27) -> 474714.24
A27: Tăng trưởng diện tích | B27: % | D27: =D26/C26-1 -> 0.5 | E27: =E26/D26-1 -> 0.2 | F27: =F152*INDEX($C$142:$E$142,$C$3) -> 0.3 | G27: =G152*INDEX($C$142:$E$142,$C$3) -> 0.3 | H27: =H152*INDEX($C$142:$E$142,$C$3) -> 0.4 | I27: =I152*INDEX($C$142:$E$142,$C$3) -> 0.32 | J27: =J152*INDEX($C$142:$E$142,$C$3) -> 0.25 | K27: Lý do: bám theo tăng trưởng TMĐT 18–25%/năm và khách hàng nội thất xuất khẩu; năm 2028 +40% nhờ công suất mới. Nguồn: Mục 3.2.2 (VECOM; Bộ Công Thương); BCTC 2023–2025.
A28: Doanh thu nội thất/TMĐT | B28: nghìn đồng | C28: ='Income Statement'!B8 -> 1520000 | D28: ='Income Statement'!C8 -> 2280000 | E28: ='Income Statement'!D8 -> 2736000 | F28: =F26*F24 -> 3610152 | G28: =G26*G24 -> 4763595.6 | H28: =H26*H24 -> 6769069.3 | I28: =I26*I24 -> 9069199 | J28: =J26*J24 -> 11506546
A30: A4. Đệm bảo vệ thiết bị, linh kiện điện tử
A31: Giá bình quân | B31: nghìn đ/m² | E31: 40 | F31: =E31*(1+F32) -> 40.6 | G31: =F31*(1+G32) -> 41.209 | H31: =G31*(1+H32) -> 41.827135 | I31: =H31*(1+I32) -> 42.454542 | J31: =I31*(1+J32) -> 43.09136 | K31: Lý do: trung điểm khung 25.000–55.000đ/m² của khay EPE/EPE chống tĩnh điện mà sản phẩm thay thế. Nguồn: báo giá khay EPE trên thị trường (2026); Mục 3.2.6.
A32: Tăng giá | B32: %/năm | F32: =F25 -> 0.015 | G32: =G25 -> 0.015 | H32: =H25 -> 0.015 | I32: =I25 -> 0.015 | J32: =J25 -> 0.015
A33: Diện tích quy đổi | B33: m² | C33: =C35/$E$31 -> 0 | D33: =D35/$E$31 -> 14150 | E33: =E35/$E$31 -> 29715 | F33: =E33*(1+F34) -> 47544 | G33: =F33*(1+G34) -> 71316 | H33: =G33*(1+H34) -> 121237.2 | I33: =H33*(1+I34) -> 175793.94 | J33: =I33*(1+J34) -> 228532.12
A34: Tăng trưởng diện tích | B34: % | E34: =E33/D33-1 -> 1.1 | F34: =F153*INDEX($C$142:$E$142,$C$3) -> 0.6 | G34: =G153*INDEX($C$142:$E$142,$C$3) -> 0.5 | H34: =H153*INDEX($C$142:$E$142,$C$3) -> 0.7 | I34: =I153*INDEX($C$142:$E$142,$C$3) -> 0.45 | J34: =J153*INDEX($C$142:$E$142,$C$3) -> 0.3 | K34: Lý do: nền nhỏ (1,2 tỷ đồng năm 2025); thay thế khay EPS/EPE cho khách hàng FDI điện tử khi chuỗi cung ứng xuất khẩu yêu cầu xanh hóa. Nguồn: Mục 3.2.2 (xuất khẩu 475 tỷ USD năm 2025, FDI chiếm 80%); BCTC 2024–2025.
A35: Doanh thu điện tử | B35: nghìn đồng | C35: ='Income Statement'!B9 -> 0 | D35: ='Income Statement'!C9 -> 566000 | E35: ='Income Statement'!D9 -> 1188600 | F35: =F33*F31 -> 1930286.4 | G35: =G33*G31 -> 2938861 | H35: =H33*H31 -> 5071004.7 | I35: =I33*I31 -> 7463251.2 | J35: =J33*J31 -> 9847760
A37: Tổng doanh thu gộp | B37: nghìn đồng | C37: =C14+C21+C28+C35 -> 19595000 | D37: =D14+D21+D28+D35 -> 31162000 | E37: =E14+E21+E28+E35 -> 47881700 | F37: =F14+F21+F28+F35 -> 64122676 | G37: =G14+G21+G28+G35 -> 80302739 | H37: =H14+H21+H28+H35 -> 1.1117992e+08 | I37: =I14+I21+I28+I35 -> 1.4260255e+08 | J37: =J14+J21+J28+J35 -> 1.7151838e+08
A38: Khoản giảm trừ / doanh thu gộp | B38: % | C38: =-'Income Statement'!B11/C37 -> 0.008 | D38: =-'Income Statement'!C11/D37 -> 0.0075 | E38: =-'Income Statement'!D11/E37 -> 0.007 | F38: 0.007 | G38: 0.007 | H38: 0.007 | I38: 0.007 | J38: 0.007 | K38: Lý do: giữ mức 2025 (0,70% doanh thu gộp), xu hướng giảm từ 0,80% (2023). Nguồn: BCTC 2023–2025 (đề bài).
A39: Doanh thu thuần | B39: nghìn đồng | C39: ='Income Statement'!B13 -> 19438240 | D39: ='Income Statement'!C13 -> 30928285 | E39: ='Income Statement'!D13 -> 47546528 | F39: =F37*(1-F38) -> 63673817 | G39: =G37*(1-G38) -> 79740620 | H39: =H37*(1-H38) -> 1.1040166e+08 | I39: =I37*(1-I38) -> 1.4160433e+08 | J39: =J37*(1-J38) -> 1.7031775e+08
A40: Tăng trưởng doanh thu thuần | B40: % | D40: =D39/C39-1 -> 0.59110521 | E40: =E39/D39-1 -> 0.53731538 | F40: =F39/E39-1 -> 0.33918962 | G40: =G39/F39-1 -> 0.25232982 | H40: =H39/G39-1 -> 0.38450974 | I40: =I39/H39-1 -> 0.2826286 | J40: =J39/I39-1 -> 0.20277215
A41: Tỷ trọng F&B/FMCG trong doanh thu gộp | B41: % | C41: =C14/C37 -> 0.76830824 | D41: =D14/D37 -> 0.77299275 | E41: =E14/E37 -> 0.79485565 | F41: =F14/F37 -> 0.79913527 | G41: =G14/G37 -> 0.79407509 | H41: =H14/H37 -> 0.78976794 | I41: =I14/I37 -> 0.7850707 | J41: =J14/J37 -> 0.77895333
A43: A5. Kiểm tra công suất (vòng quay tài sản) & thị phần ngầm định
A44: Nguyên giá TSCĐ bình quân | B44: nghìn đồng | C44: =(SUM('Balance Sheet'!D29:D31)+C96)/2 -> 17289500 | D44: =(C96+D96)/2 -> 22946800 | E44: =(D96+E96)/2 -> 28641860 | F44: =(E96+F96)/2 -> 37551502 | G44: =(F96+G96)/2 -> 69834585 | H44: =(G96+H96)/2 -> 1.0237439e+08 | I44: =(H96+I96)/2 -> 1.160787e+08 | J44: =(I96+J96)/2 -> 1.3167481e+08
A45: Vòng quay nguyên giá TSCĐ (DT thuần / NG bình quân) | B45: lần | C45: =C39/C44 -> 1.1242801 | D45: =D39/D44 -> 1.3478256 | E45: =E39/E44 -> 1.6600363 | F45: =F39/F44 -> 1.6956397 | G45: =G39/G44 -> 1.14185 | H45: =H39/H44 -> 1.078411 | I45: =I39/I44 -> 1.2198993 | J45: =J39/J44 -> 1.2934725 | K45: Vòng quay 2025 = 1,66x. Nếu vòng quay dự phóng < 2025 → còn công suất trống (không cần CAPEX lớn tiếp theo); nếu >> 2025 → dự báo vượt công suất.
A46: Tỷ giá USD/VND bình quân | B46: VND/USD | E46: 26000 | F46: 26300 | G46: =F46*(1+0.02) -> 26826 | H46: =G46*(1+0.02) -> 27362.52 | I46: =H46*(1+0.02) -> 27909.77 | J46: =I46*(1+0.02) -> 28467.966 | K46: Lý do: dùng để quy đổi doanh thu sang USD khi so với TAM/SAM của IMARC. 2025: 26.000; 2026: 26.300; sau đó VND mất giá 2%/năm. Nguồn: Vietcombank (tỷ giá bán ra); MBS Research dự báo 26.800–27.000 cuối 2026 (Mục 3.1.4).
...

Sheet Pro Forma
A1: Báo cáo kết quả hoạt động kinh doanh (dự kiến) 5 năm
B2: 0 | C2: 1 | D2: 2 | E2: 3 | F2: 4 | G2: 5
B3: ='Income Statement'!D4 -> 2025 | C3: =B3+1 -> 2026 | D3: =C3+1 -> 2027 | E3: =D3+1 -> 2028 | F3: =E3+1 -> 2029 | G3: =F3+1 -> 2030
A4: Doanh thu | B4: ='Income Statement'!D13 -> 47546528 | C4: =B4*(1+Assumption!E4) -> 63673817 | D4: =C4*(1+Assumption!F4) -> 79740620 | E4: =D4*(1+Assumption!G4) -> 1.1040166e+08 | F4: =E4*(1+Assumption!H4) -> 1.4160433e+08 | G4: =F4*(1+Assumption!I4) -> 1.7031775e+08
A5: Giá vốn hàng bán (gồm 70% tiền lương, 90% khấu hao) | B5: ='Income Statement'!D20 -> 23281582 | C5: =C4*Assumption!E5 -> 30719170 | D5: =D4*Assumption!F5 -> 39459963 | E5: =E4*Assumption!G5 -> 60909642 | F5: =F4*Assumption!H5 -> 74954279 | G5: =G4*Assumption!I5 -> 89256897
A6: Lợi nhuận gộp | B6: =B4-B5 -> 24264946 | C6: =C4-C5 -> 32954647 | D6: =D4-D5 -> 40280657 | E6: =E4-E5 -> 49492023 | F6: =F4-F5 -> 66650054 | G6: =G4-G5 -> 81060851
A7: Chi phí bán hàng & QLDN (gồm 30% tiền lương, 10% khấu hao) | B7: ='Income Statement'!D63 -> 19702269 | C7: =C4*Assumption!E6 -> 25312537 | D7: =D4*Assumption!F6 -> 31281149 | E7: =E4*Assumption!G6 -> 43224542 | F7: =F4*Assumption!H6 -> 52803208 | G7: =G4*Assumption!I6 -> 61405287
A8: Chi phí thuê cửa hàng | B8: 0 | C8: 0 | D8: 0 | E8: 0 | F8: 0 | G8: 0
A9: Khấu hao (ghi nhớ – đã phân bổ vào GVHB và CPBH & QLDN) | B9: ='Income Statement'!D71 -> 3131952 | C9: =Assumption!$D$17*B22 -> 3742094.4 | D9: =Assumption!$D$17*C22 -> 5270266 | E9: =Assumption!$D$17*D22 -> 11490034 | F9: =Assumption!$D$17*E22 -> 13079818 | G9: =Assumption!$D$17*F22 -> 14779070
A10: Lợi nhuận trước thuế và lãi vay (EBIT) | B10: =B6-B7-B8 -> 4562677.2 | C10: =C6-C7-C8 -> 7642109.6 | D10: =D6-D7-D8 -> 8999508.6 | E10: =E6-E7-E8 -> 6267480.2 | F10: =F6-F7-F8 -> 13846846 | G10: =G6-G7-G8 -> 19655564
A11: Chi phí tài chính | B11: ='Income Statement'!D69 -> 142182 | C11: =C4*Assumption!E7 -> 160260 | D11: =D4*Assumption!F7 -> 1715202.1 | E11: =E4*Assumption!G7 -> 3270144.2 | F11: =F4*Assumption!H7 -> 2959155.8 | G11: =G4*Assumption!I7 -> 2337178.9
A12: Lợi nhuận trước thuế | B12: =B10-B11 -> 4420495.2 | C12: =C10-C11 -> 7481849.6 | D12: =D10-D11 -> 7284306.5 | E12: =E10-E11 -> 2997336 | F12: =F10-F11 -> 10887690 | G12: =G10-G11 -> 17318385
A13: Thuế TNDN | B13: 0 | C13: =Drivers!F137 -> 902709.76 | D13: =Drivers!G137 -> 1456861.3 | E13: =Drivers!H137 -> 599467.2 | F13: =Drivers!I137 -> 2177538 | G13: =Drivers!J137 -> 3463677
A14: Lợi nhuận sau thuế | B14: =B12-B13 -> 4420495.2 | C14: =C12-C13 -> 6579139.9 | D14: =D12-D13 -> 5827445.2 | E14: =E12-E13 -> 2397868.8 | F14: =F12-F13 -> 8710152.1 | G14: =G12-G13 -> 13854708
A17: Tính toán chi tiết:
A19: Chi phí đầu tư tài sản cố định (CAPEX)
B21: =B3 -> 2025 | C21: =B21+1 -> 2026 | D21: =C21+1 -> 2027 | E21: =D21+1 -> 2028 | F21: =E21+1 -> 2029 | G21: =F21+1 -> 2030
A22: Tài sản dài hạn | B22: =SUM('Balance Sheet'!G29:G31) -> 31184120 | C22: =B22+C25 -> 43918883 | D22: =C22+D25 -> 95750286 | E22: =D22+E25 -> 1.0899849e+08 | F22: =E22+F25 -> 1.2315892e+08 | G22: =F22+G25 -> 1.4019069e+08
A23: Khấu hao lũy kế | B23: ='Balance Sheet'!G26 -> 9789432 | C23: =B23+C9 -> 13531526 | D23: =C23+D9 -> 18801792 | E23: =D23+E9 -> 30291827 | F23: =E23+F9 -> 43371645 | G23: =F23+G9 -> 58150715
A24: Tổng tài sản dài hạn (ròng) | B24: =B22-B23 -> 21394688 | C24: =C22-C23 -> 30387357 | D24: =D22-D23 -> 76948494 | E24: =E22-E23 -> 78706659 | F24: =F22-F23 -> 79787274 | G24: =G22-G23 -> 82039979
A25: CAPEX | B25: =B22-SUM('Balance Sheet'!F29:F31) -> 5084520 | C25: =C4*Assumption!E13 -> 12734763 | D25: =D4*Assumption!F13 -> 51831403 | E25: =E4*Assumption!G13 -> 13248200 | F25: =F4*Assumption!H13 -> 14160433 | G25: =G4*Assumption!I13 -> 17031775
A28: Điều chỉnh Vốn lưu động ròng
B30: =B21 -> 2025 | C30: =B30+1 -> 2026 | D30: =C30+1 -> 2027 | E30: =D30+1 -> 2028 | F30: =E30+1 -> 2029 | G30: =F30+1 -> 2030
A31: Tài sản ngắn hạn (ngoài tiền) | B31: ='Balance Sheet'!G22-'Balance Sheet'!G7 -> 7589370 | C31: =C4*Assumption!E8 -> 10432965 | D31: =D4*Assumption!F8 -> 13990014 | E31: =E4*Assumption!G8 -> 21603011 | F31: =F4*Assumption!H8 -> 28367035 | G31: =G4*Assumption!I8 -> 33598868
A32: Hàng tồn kho | B32: ='Balance Sheet'!G10 -> 3748500 | C32: =C31*Assumption!E10 -> 4745934 | D32: =D31*Assumption!F10 -> 5994105.1 | E32: =E31*Assumption!G10 -> 9322716.3 | F32: =F31*Assumption!H10 -> 11064149 | G32: =G31*Assumption!I10 -> 12787439
A33: Khoản phải thu ngắn hạn | B33: ='Balance Sheet'!G13 -> 1767780 | C33: =C31*Assumption!E11 -> 3140078.6 | D33: =D31*Assumption!F11 -> 4806284 | E33: =E31*Assumption!G11 -> 7864228.2 | F33: =F31*Assumption!H11 -> 11638712 | G33: =G31*Assumption!I11 -> 13998719
A34: Nợ ngắn hạn (ngoài vay) | B34: ='Balance Sheet'!G58-'Balance Sheet'!G48 -> 342732 | C34: =C4*Assumption!E9 -> 601941.04 | D34: =D4*Assumption!F9 -> 878773.85 | E34: =E4*Assumption!G9 -> 1552619.9 | F34: =F4*Assumption!H9 -> 1942831.1 | G34: =G4*Assumption!I9 -> 2359704.9
A35: Khoản phải trả ngắn hạn | B35: ='Balance Sheet'!G41 -> 263640 | C35: =C34*Assumption!E12 -> 474593.4 | D35: =D34*Assumption!F12 -> 719292.61 | E35: =E34*Assumption!G12 -> 1331816.6 | F35: =F34*Assumption!H12 -> 1659622.4 | G35: =G34*Assumption!I12 -> 2019069.4
A36: Vốn lưu động hoạt động ròng (TSNH ngoài tiền − Nợ NH ngoài vay) | B36: =B31-B34 -> 7246638 | C36: =C31-C34 -> 9831024.3 | D36: =D31-D34 -> 13111240 | E36: =E31-E34 -> 20050391 | F36: =F31-F34 -> 26424204 | G36: =G31-G34 -> 31239164
A37: Biến động VLĐ ròng | C37: =C36-B36 -> 2584386.3 | D37: =D36-C36 -> 3280215.7 | E37: =E36-D36 -> 6939151.1 | F37: =F36-E36 -> 6373812.7 | G37: =G36-F36 -> 4814959.7
A40: Xác định nhu cầu vốn
A41: Cash Flow Statment Pro-forma
B42: 0 | C42: 1 | D42: 2 | E42: 3 | F42: 4 | G42: 5
B43: =B30 -> 2025 | C43: =B43+1 -> 2026 | D43: =C43+1 -> 2027 | E43: =D43+1 -> 2028 | F43: =E43+1 -> 2029 | G43: =F43+1 -> 2030
A44: ='Cash Flow Statement'!A5 -> Hoạt động kinh doanh
A45: ='Cash Flow Statement'!B6 -> Lợi nhuận sau thuế | B45: =B14 -> 4420495.2 | C45: =C14 -> 6579139.9 | D45: =D14 -> 5827445.2 | E45: =E14 -> 2397868.8 | F45: =F14 -> 8710152.1 | G45: =G14 -> 13854708
A46: ='Cash Flow Statement'!B8 -> Khấu hao | B46: =B9 -> 3131952 | C46: =C9 -> 3742094.4 | D46: =D9 -> 5270266 | E46: =E9 -> 11490034 | F46: =F9 -> 13079818 | G46: =G9 -> 14779070
A47: Biến động TSNH | B47: =SUM('Cash Flow Statement'!E11:E13) -> -1343670 | C47: =B31-C31 -> -2843595.4 | D47: =C31-D31 -> -3557048.5 | E47: =D31-E31 -> -7612997.2 | F47: =E31-F31 -> -6764023.8 | G47: =F31-G31 -> -5231833.5
A48: Biến động Nợ NH | B48: =SUM('Cash Flow Statement'!E15:E17) -> 73692 | C48: =C34-B34 -> 259209.04 | D48: =D34-C34 -> 276832.81 | E48: =E34-D34 -> 673846.09 | F48: =F34-E34 -> 390211.12 | G48: =G34-F34 -> 416873.82
A49: Lưu chuyển tiền thuần từ HĐKD | B49: =SUM(B45:B48) -> 6282469.2 | C49: =SUM(C45:C48) -> 7736847.9 | D49: =SUM(D45:D48) -> 7817495.5 | E49: =SUM(E45:E48) -> 6948752.1 | F49: =SUM(F45:F48) -> 15416158 | G49: =SUM(G45:G48) -> 23818819
...

Sheet DCF
A1: Dòng tiền tự do (FCFF) của doanh nghiệp
C3: 1 | D3: =C3+1 -> 2 | E3: =D3+1 -> 3 | F3: =E3+1 -> 4 | G3: =F3+1 -> 5
B4: ='Income Statement'!D4 -> 2025 | C4: =B4+1 -> 2026 | D4: =C4+1 -> 2027 | E4: =D4+1 -> 2028 | F4: =E4+1 -> 2029 | G4: =F4+1 -> 2030 | H4: =G4+1 -> 2031
A5: Lợi nhuận sau thuế trước lãi vay EBIT*(1-t) | C5: ='Pro Forma'!C10-Drivers!F135*MAX(0,'Pro Forma'!C10-Drivers!F133) -> 6712155.7 | D5: ='Pro Forma'!D10-Drivers!G135*MAX(0,'Pro Forma'!D10-Drivers!G133) -> 7199606.9 | E5: ='Pro Forma'!E10-Drivers!H135*MAX(0,'Pro Forma'!E10-Drivers!H133) -> 5013984.2 | F5: ='Pro Forma'!F10-Drivers!I135*MAX(0,'Pro Forma'!F10-Drivers!I133) -> 11077477 | G5: ='Pro Forma'!G10-Drivers!J135*MAX(0,'Pro Forma'!G10-Drivers!J133) -> 15724451
A6: + Khấu hao | C6: ='Pro Forma'!C9 -> 3742094.4 | D6: ='Pro Forma'!D9 -> 5270266 | E6: ='Pro Forma'!E9 -> 11490034 | F6: ='Pro Forma'!F9 -> 13079818 | G6: ='Pro Forma'!G9 -> 14779070
A7: - Điều chỉnh VLĐ | C7: ='Pro Forma'!C37 -> 2584386.3 | D7: ='Pro Forma'!D37 -> 3280215.7 | E7: ='Pro Forma'!E37 -> 6939151.1 | F7: ='Pro Forma'!F37 -> 6373812.7 | G7: ='Pro Forma'!G37 -> 4814959.7
A8: - CAPEX | C8: ='Pro Forma'!C25 -> 12734763 | D8: ='Pro Forma'!D25 -> 51831403 | E8: ='Pro Forma'!E25 -> 13248200 | F8: ='Pro Forma'!F25 -> 14160433 | G8: ='Pro Forma'!G25 -> 17031775
H9: FCFF 2031 chuẩn hóa
A10: Dòng tiền tự do (FCFF) | C10: =C5+C6-C7-C8 -> -4864899.6 | D10: =D5+D6-D7-D8 -> -42641746 | E10: =E5+E6-E7-E8 -> -3683332.4 | F10: =F5+F6-F7-F8 -> 3623049.1 | G10: =G5+G6-G7-G8 -> 8656787.1 | H10: =G5*(1+Assumption!D16)*(1-Assumption!D16/Assumption!D19) -> 10563519 | I10: FCFF 2031 = NOPAT 2031 × (1 − g/RONIC): phần tái đầu tư chỉ vừa đủ cho tăng trưởng g; RONIC = ROIC 2030E (Assumption!D19).
A12: Giá trị cuối kỳ tại t=5 = FCFF 2031 / (WACC − g) | G12: =H10/(Assumption!D18-Assumption!D16) -> 1.2229362e+08
A14: Giá trị hiện tại của các dòng tiền (FCFF; năm 2030 gồm giá trị cuối kỳ) | C14: =C10/(1+Assumption!$D$18)^C3 -> -4281056.3 | D14: =D10/(1+Assumption!$D$18)^D3 -> -33020914 | E14: =E10/(1+Assumption!$D$18)^E3 -> -2509990.5 | F14: =F10/(1+Assumption!$D$18)^F3 -> 2172613.4 | G14: =(G10+G12)/(1+Assumption!$D$18)^G3 -> 69102241
A16: Giá trị doanh nghiệp | C16: =SUM(C14:G14) -> 31462893
A19: Nhu cầu vốn | B19: ='Pro Forma'!B63 -> 37610763
A20: Tỷ lệ nắm giữ | B20: =B19/B21 -> 0.53420936
A21: Post-money value | B21: =B22+B19 -> 70404538
A22: Pre-money value | B22: =C16+'Balance Sheet'!G7-'Balance Sheet'!G48-'Balance Sheet'!G61 -> 32793775 | D22: Pitch: Kêu gọi | E22: =B19 -> 37610763 | F22: nghìn đồng tương ứng | G22: =B20 -> 0.53420936 | H22: cổ phần.
A26: CẦU NỐI EV → VỐN CSH & KIỂM TRA
A27: PV dòng tiền tự do 2026–2030 | B27: =SUM(C14:F14)+G10/(1+Assumption!D18)^G3 -> -33071180
A28: PV giá trị cuối kỳ | B28: =G12/(1+Assumption!D18)^G3 -> 64534073
A29: Giá trị doanh nghiệp (EV) | B29: =C16 -> 31462893
A30: Tỷ trọng giá trị cuối kỳ / EV | B30: =B28/B29 -> 2.0511169
A31: (+) Tiền mặt 31/12/2025 | B31: ='Balance Sheet'!G7 -> 2933481.8
A32: (−) Nợ vay 31/12/2025 | B32: ='Balance Sheet'!G48+'Balance Sheet'!G61 -> 1602600
A33: Giá trị vốn CSH trước gọi vốn (pre-money) | B33: =B29+B31-B32 -> 32793775
A34: EV/EBITDA 2025A ngầm định | B34: =B29/Drivers!E76 -> 4.0889421
A35: EV/EBITDA 2026E ngầm định | B35: =B29/Drivers!F76 -> 2.7637324
A36: P/E 2026E ngầm định (pre-money) | B36: =B33/'Income Statement'!E80 -> 4.984508
A37: P/B 2025A ngầm định | B37: =B33/'Balance Sheet'!G76 -> 1.0941395
A38: Giá trị cuối kỳ nếu không chuẩn hóa = FCFF 2030 × (1 + g)/(WACC − g) | B38: =G10*(1+Assumption!D16)/(Assumption!D18-Assumption!D16) -> 1.052304e+08
A39: ROIC 2030E = NOPAT / (TSCĐ ròng + VLĐ) | B39: =G5/('Pro Forma'!G24+'Pro Forma'!G36) -> 0.13881153
A40: Tỷ lệ tái đầu tư trong giá trị cuối kỳ = g / RONIC | B40: =Assumption!D16/Assumption!D19 -> 0.36020062
A41: Kiểm tra: pre-money = B22 | B41: =B33-B22 -> 0

Sheet VCM
A1: The VC Method | C1: =DCF!G4 -> 2030
A3: Tỷ lệ chiết khấu có điều chỉnh
A5: Số kỳ | B5: =DCF!G3 -> 5 | D5: Nhu cầu vốn | E5: =DCF!B19 -> 37610763
A6: Tỷ lệ thất bại của VC | B6: 0.4 | C6: Giả định: theo hướng dẫn của BTL, DN giai đoạn đầu tăng trưởng có z = 35–45%; lấy 40% (trung điểm). | D6: Giá trị thoái vốn kỳ vọng | E6: =B39 -> 1.9869224e+08
A7: Tỷ lệ chiết khấu (WACC) | B7: ='Discount rate'!E5 -> 0.13637833
D8: Post-money value | E8: =E6/(1+B9)^B5 -> 62909673
A9: Tỷ lệ chiết khấu có điều chỉnh p = (1 + r)/(1 − z)^(1/n) − 1 | B9: =(1+B7)/(1-B6)^(1/B5)-1 -> 0.25861439 | C9: Công thức giáo trình: (1 + p)^n = (1 + r)^n/(1 − z), với r = WACC (B7), z = B6, n = 5 năm. | D9: Tỷ lệ sở hữu của NĐT mới | E9: =E5/E8 -> 0.59785342
D11: Pre-money value | E11: =E8-E5 -> 25298910
D12: Tỷ lệ sở hữu của Founder và NĐT cũ | E12: =1-E9 -> 0.40214658
A15: Pitch: Kêu gọi | B15: =E5 -> 37610763 | C15: nghìn đồng tương ứng | D15: =E9 -> 0.59785342 | E15: cổ phần.
A19: Tỷ lệ thất bại theo giai đoạn đầu tư VC (đề bài) | B19: Thấp | C19: Cao | D19: Trung điểm
A20: Ươm mầm | B20: 0.65 | C20: 0.8 | D20: =AVERAGE(B20:C20) -> 0.725 | E20: Nguồn: đề bài (BTL, Mục III.1 – tỷ lệ thất bại tại mỗi giai đoạn đầu tư của VC); bảng dùng cho Mục 8 (giai đoạn chưa có doanh thu).
A21: Thử nghiệm | B21: 0.5 | C21: 0.65 | D21: =AVERAGE(B21:C21) -> 0.575
A22: Đầu tăng trưởng | B22: 0.35 | C22: 0.45 | D22: =AVERAGE(B22:C22) -> 0.4
A23: Cuối tăng trưởng | B23: 0.2 | C23: 0.3 | D23: =AVERAGE(B23:C23) -> 0.25
A25: Giai đoạn của AgriPack (kết luận mục 2) | B25: Đầu tăng trưởng | C25: Lý do: doanh thu 47,5 tỷ, tăng 54–59%/năm, LNST và FCF vừa dương năm 2025, D/E 6,5%. Nguồn: kết luận Mục 2.
A27: GIÁ TRỊ THOÁI VỐN CUỐI 2030
A28: LNST 2030E | B28: ='Income Statement'!I80 -> 13854708
A29: P/E thoát vốn | B29: 9.4 | C29: Lý do: P/E ngành Containers & Packaging (ICB cấp 4) năm 2026: 9,43x; trung vị mẫu 14 DN: xem Multiples!G22. Nguồn: FiinX (giá đóng cửa 28/9/2026).
A30: Giá trị vốn CSH theo P/E | B30: =B28*B29 -> 1.3023426e+08
A31: EBITDA 2030E | B31: ='Income Statement'!I82 -> 34434634
A32: EV/EBITDA thoát vốn | B32: 8 | C32: Lý do: EV/EBITDA ngành Containers & Packaging 2026: 7,99x (2025: 7,5x). Nguồn: FiinX (giá đóng cửa 28/9/2026).
A33: EV theo EV/EBITDA | B33: =B31*B32 -> 2.7547708e+08
A34: (+) Tiền mặt 2030E | B34: ='Balance Sheet'!L7 -> 11935048
A35: (−) Nợ vay 2030E | B35: ='Balance Sheet'!L48+'Balance Sheet'!L61 -> 20261905
A36: Giá trị vốn CSH theo EV/EBITDA | B36: =B33+B34-B35 -> 2.6715022e+08
A37: Đối chiếu: giá trị vốn CSH theo DCF tại 2030 (TV + tiền − nợ) | B37: =DCF!G12+B34-B35 -> 1.1396676e+08
A38: EV/EBITDA ngầm định của P/E thoát vốn | B38: =(B30-B34+B35)/B31 -> 4.023888
A39: Giá trị thoái vốn sử dụng (bình quân P/E và EV/EBITDA) | B39: =AVERAGE(B30,B36) -> 1.9869224e+08
A41: IRR kỳ vọng của NĐT nếu thành công | B41: =(E6*E9/E5)^(1/B5)-1 -> 0.25861439
A42: IRR kỳ vọng có tính xác suất thất bại (= WACC) | B42: =((1-B6)*E6*E9/E5)^(1/B5)-1 -> 0.13637833

Sheet Multiples
A1: ĐỊNH GIÁ BẰNG BỘI SỐ SO SÁNH (MULTIPLES / COMPARABLES) – AgriPack
A2: Đơn vị: tỷ đồng; bội số: lần. Mẫu so sánh: 16 DN bao bì niêm yết (FiinX, giá đóng cửa 28/9/2026; BCTC quý đến Q2/2026, TTM). Cột H = 1: đưa vào mẫu; loại MCP (EV/EBITDA 36x, P/E 84x do lợi nhuận quá thấp) và PBT (DN thương mại, EV/EBITDA ≈ 0).
A4: Mã | B4: Sàn | C4: Phân khúc | D4: DT TTM (tỷ) | E4: Biên EBITDA (%) | F4: EV/EBITDA (x) | G4: P/E (x) | H4: Đưa vào mẫu | I4: EV/EBITDA (mẫu) | J4: P/E (mẫu) | K4: Nguồn
A5: DHC | B5: HOSE | C5: Giấy, bao bì carton | D5: 3938 | E5: 18.9 | F5: 6.35 | G5: 7.48 | H5: 1 | I5: =IF(H5=1,F5,"") -> 6.35 | J5: =IF(H5=1,G5,"") -> 7.48 | K5: FiinX: BCTC 4 quý gần nhất đến Q2/2026; giá đóng cửa 28/9/2026
A6: TDP | B6: HOSE | C6: Bao bì nhựa | D6: 5488 | E6: 8.3 | F6: 8.98 | G6: 20.51 | H6: 1 | I6: =IF(H6=1,F6,"") -> 8.98 | J6: =IF(H6=1,G6,"") -> 20.51 | K6: FiinX: BCTC 4 quý gần nhất đến Q2/2026; giá đóng cửa 28/9/2026
A7: AAA | B7: HOSE | C7: Nhựa, nhựa sinh học | D7: 9243 | E7: 14.2 | F7: 3.85 | G7: 5.16 | H7: 1 | I7: =IF(H7=1,F7,"") -> 3.85 | J7: =IF(H7=1,G7,"") -> 5.16 | K7: FiinX: BCTC 4 quý gần nhất đến Q2/2026; giá đóng cửa 28/9/2026
A8: APH | B8: HOSE | C8: Bao bì nhựa (holding) | D8: 9252 | E8: 14 | F8: 5.05 | G8: 6.98 | H8: 1 | I8: =IF(H8=1,F8,"") -> 5.05 | J8: =IF(H8=1,G8,"") -> 6.98 | K8: FiinX: BCTC 4 quý gần nhất đến Q2/2026; giá đóng cửa 28/9/2026
A9: HHP | B9: HOSE | C9: Giấy bao bì | D9: 3112 | E9: 9.3 | F9: 13.71 | G9: 32.9 | H9: 1 | I9: =IF(H9=1,F9,"") -> 13.71 | J9: =IF(H9=1,G9,"") -> 32.9 | K9: FiinX: BCTC 4 quý gần nhất đến Q2/2026; giá đóng cửa 28/9/2026
A10: INN | B10: HNX | C10: Bao bì giấy, in | D10: 1921 | E10: 14.9 | F10: 2.66 | G10: 7.29 | H10: 1 | I10: =IF(H10=1,F10,"") -> 2.66 | J10: =IF(H10=1,G10,"") -> 7.29 | K10: FiinX: BCTC 4 quý gần nhất đến Q2/2026; giá đóng cửa 28/9/2026
A11: ILS | B11: UPCoM | C11: Bao bì khác | D11: 319 | E11: 16.4 | F11: 13.33 | G11: 16.64 | H11: 1 | I11: =IF(H11=1,F11,"") -> 13.33 | J11: =IF(H11=1,G11,"") -> 16.64 | K11: FiinX: BCTC 4 quý gần nhất đến Q2/2026; giá đóng cửa 28/9/2026
